Workbook

Sheet DIAGNÓSTICO
A1: PORTAFOLIO | B1: TIPO DE AUDITORÍA | C1: GESTOR | D1: VERSION | E1: CODIGO | F1: FECHA MONITOREO | G1: TIPO DE PUNTAJE | H1: CARTERA | I1: NOMBRE EJECUTIVO | J1: CEDULA TT | K1: NOMBRE TT | L1: TELEFONO | M1: FECHA DE ATENCIÃ“N | N1: CALIFICACION TOTAL | O1: DESCRIPCIÃ“N | P1: PresentaciÃ³n, | Q1: Explica el motivo de la llamada de forma clara y rÃ¡pida, | R1: Escucha Activa, | S1: Preguntar, | T1: Rebatir, | U1: Vender, | V1: Beneficios, | W1: Cierre, | X1: ActualizaciÃ³n de datos, | Y1: Despedida, | Z1: Oferta, | AA1: Conocimiento Del Producto | AB1: ModulaciÃ³n | AC1: Muletillas | AD1: Ruido Ambiente | AE1: TMO | AF1: Manejo De Emociones, | AG1: AtenciÃ³n Oportuna, | AH1: Tiempos Muertos, | AI1: Corte De ComunicaciÃ³n, | AJ1: TipificaciÃ³n, | AK1: ObservaciÃ³n, | AL1: Registro De Datos Actualizados, | AM1: Agendamiento, | AN1: Cumplimiento En Seguimiento, | AO1: Realiza DevoluciÃ³n De Llamada | AP1: Uso De Medios, | AQ1: Protocolo De GestiÃ³n, | AR1: Protocolo De GestiÃ³n | AS1: Calificacionnegativa | AT1: Cuartil Actual
A2: EMPRESARIAL VIGENTE | B2: DIAGNÓSTICO | C2: cristian.gallego543 | D2: 3 | E2: CODIGO PS-F-03 | F2: 2025-09-12 15:44:34.03636 | G2: KPI | H2: CrediOrbe Vigente | I2: cristian.cifuentes013 | J2: 2036644 | K2: YESICA CATHERINE BAUTISTA PALACIO | L2: 3188120410 | M2: 45903 | N2: 6.9 | O2: LLAMADA TELEFÃ“NICATIPO AUDITORIA | P2: 0 | Q2: 0 | R2: 0 | S2: 0 | T2: 0 | U2: 3.45 | V2: 3.45 | W2: 0 | X2: 0 | Y2: 0 | Z2: 0 | AA2: 0 | AB2: 0 | AC2: 0 | AD2: 0 | AE2: 0 | AF2: 0 | AG2: 0 | AH2: 0 | AI2: 0 | AJ2: 0 | AK2: 0 | AL2: 0 | AM2: 0 | AN2: 0 | AO2: 0 | AP2: 0 | AQ2: 0 | AR2: 0 | AS2: =SUMIF(P2:AR2,3.45) -> 6.9 | AT2: 100
A3: EMPRESARIAL VIGENTE | B3: DIAGNÓSTICO | C3: cristian.gallego543 | D3: 3 | E3: CODIGO PS-F-03 | F3: 2025-09-05 14:26:25.633078 | G3: KPI | H3: CrediOrbe Vigente | I3: cristian.cifuentes013 | J3: 2012501 | K3: Marelis yanilis orozco cabarcas | L3: 3124250477 | M3: 45895 | N3: 13.8 | O3: LLAMADA TELEFÃ“NICATIPO AUDITORIA | P3: 0 | Q3: 0 | R3: 0 | S3: 0 | T3: 3.45 | U3: 3.45 | V3: 3.45 | W3: 3.45 | X3: 0 | Y3: 0 | Z3: 0 | AA3: 0 | AB3: 0 | AC3: 0 | AD3: 0 | AE3: 0 | AF3: 0 | AG3: 0 | AH3: 0 | AI3: 0 | AJ3: 0 | AK3: 0 | AL3: 0 | AM3: 0 | AN3: 0 | AO3: 0 | AP3: 0 | AQ3: 0 | AR3: 0 | AS3: =SUMIF(P3:AR3,3.45) -> 13.8
A4: EMPRESARIAL VIGENTE | B4: DIAGNÓSTICO | C4: cristian.gallego543 | D4: 3 | E4: CODIGO PS-F-03 | F4: 2025-09-05 11:01:52.205482 | G4: KPI | H4: CrediOrbe Vigente | I4: cristian.cifuentes013 | J4: 1980561 | K4: YEIMY KATHERINE VALDELAMAR MARIN | L4: 3136765995 | M4: 45895 | N4: 20.7 | O4: LLAMADA TELEFÃ“NICATIPO AUDITORIA | P4: 0 | Q4: 3.45 | R4: 0 | S4: 0 | T4: 3.45 | U4: 3.45 | V4: 3.45 | W4: 3.45 | X4: 0 | Y4: 3.45 | Z4: 0 | AA4: 0 | AB4: 0 | AC4: 0 | AD4: 0 | AE4: 0 | AF4: 0 | AG4: 0 | AH4: 0 | AI4: 0 | AJ4: 0 | AK4: 0 | AL4: 0 | AM4: 0 | AN4: 0 | AO4: 0 | AP4: 0 | AQ4: 0 | AR4: 0 | AS4: =SUMIF(P4:AR4,3.45) -> 20.7
A5: EMPRESARIAL VIGENTE | B5: DIAGNÓSTICO | C5: cristian.gallego543 | D5: 3 | E5: CODIGO PS-F-03 | F5: 2025-09-05 10:16:55.792877 | G5: KPI | H5: CrediOrbe Vigente | I5: cristian.cifuentes013 | J5: 1912585 | L5: 3136730889 | M5: 45894 | N5: 27.6 | O5: LLAMADA TELEFÃ“NICATIPO AUDITORIA | P5: 0 | Q5: 3.45 | R5: 0 | S5: 0 | T5: 3.45 | U5: 3.45 | V5: 3.45 | W5: 3.45 | X5: 0 | Y5: 3.45 | Z5: 3.45 | AA5: 0 | AB5: 0 | AC5: 0 | AD5: 0 | AE5: 0 | AF5: 0 | AG5: 0 | AH5: 0 | AI5: 0 | AJ5: 0 | AK5: 3.45 | AL5: 0 | AM5: 0 | AN5: 0 | AO5: 0 | AP5: 0 | AQ5: 0 | AR5: 0 | AS5: =SUMIF(P5:AR5,3.45) -> 27.6
A6: EMPRESARIAL VIGENTE | B6: DIAGNÓSTICO | C6: cristian.gallego543 | D6: 3 | E6: CODIGO PS-F-03 | F6: 2025-09-04 17:02:30.718431 | G6: KPI | H6: CrediOrbe Vigente | I6: cristian.cifuentes013 | J6: 1862296 | K6: MARLENY MONTIEL PRADA | L6: 3195715429 | M6: 45898 | N6: 24.15 | O6: LLAMADA TELEFÃ“NICATIPO AUDITORIA | P6: 0 | Q6: 3.45 | R6: 0 | S6: 0 | T6: 3.45 | U6: 0 | V6: 3.45 | W6: 3.45 | X6: 3.45 | Y6: 3.45 | Z6: 0 | AA6: 0 | AB6: 0 | AC6: 0 | AD6: 0 | AE6: 0 | AF6: 0 | AG6: 0 | AH6: 0 | AI6: 0 | AJ6: 0 | AK6: 0 | AL6: 0 | AM6: 0 | AN6: 0 | AO6: 0 | AP6: 0 | AQ6: 0 | AR6: 3.45 | AS6: =SUMIF(P6:AR6,3.45) -> 24.15
A7: EMPRESARIAL VIGENTE | B7: DIAGNÓSTICO | C7: CRISTIAN CIFUENTES | O7: SUBTOTAL | P7: =SUM(P2:P6) -> 0 | Q7: =SUM(Q2:Q6) -> 10.35 | R7: =SUM(R2:R6) -> 0 | S7: =SUM(S2:S6) -> 0 | T7: =SUM(T2:T6) -> 13.8 | U7: =SUM(U2:U6) -> 13.8 | V7: =SUM(V2:V6) -> 17.25 | W7: =SUM(W2:W6) -> 13.8 | ... AS7: =SUM(AS2:AS6) -> 93.15
A8: EMPRESARIAL VIGENTE | B8: DIAGNÓSTICO | C8: cristian.gallego543 | D8: 3 | E8: CODIGO PS-F-03 | F8: 2025-09-17 11:19:59.561569 | G8: KPI | H8: CrediOrbe Vigente | I8: valeria.giraldo913 | J8: 2116291 | K8: FELIPE DE JESUS GONZALEZ LOAIZA | L8: 3017616045 | M8: 45894 | N8: 13.8 | O8: LLAMADA TELEFÃ“NICATIPO AUDITORIA | P8: 3.45 | Q8: 3.45 | R8: 0 | S8: 0 | T8: 0 | U8: 0 | V8: 0 | W8: 3.45 | X8: 0 | Y8: 3.45 | Z8: 0 | AA8: 0 | AB8: 0 | AC8: 0 | AD8: 0 | AE8: 0 | AF8: 0 | AG8: 0 | AH8: 0 | AI8: 0 | AJ8: 0 | AK8: 0 | AL8: 0 | AM8: 0 | AN8: 0 | AO8: 0 | AP8: 0 | AQ8: 0 | AR8: 0 | AS8: =SUMIF(P8:AR8,3.45) -> 13.8
A9: EMPRESARIAL VIGENTE | B9: DIAGNÓSTICO | C9: cristian.gallego543 | D9: 3 | E9: CODIGO PS-F-03 | F9: 2025-09-17 09:45:07.882145 | G9: KPI | H9: CrediOrbe Vigente | I9: valeria.giraldo913 | J9: 2124205 | K9: MAYERLIN CASTILLO PERLAZA | L9: 3217239673 | M9: 45917 | N9: 10.35 | O9: LLAMADA TELEFÃ“NICATIPO AUDITORIA | P9: 3.45 | Q9: 0 | R9: 0 | S9: 0 | T9: 0 | U9: 0 | V9: 0 | W9: 0 | X9: 3.45 | Y9: 0 | Z9: 0 | AA9: 0 | AB9: 0 | AC9: 0 | AD9: 0 | AE9: 0 | AF9: 0 | AG9: 0 | AH9: 0 | AI9: 0 | AJ9: 3.45 | AK9: 0 | AL9: 0 | AM9: 0 | AN9: 0 | AO9: 0 | AP9: 0 | AQ9: 0 | AR9: 0 | AS9: =SUMIF(P9:AR9,3.45) -> 10.35
A10: EMPRESARIAL VIGENTE | B10: DIAGNÓSTICO | C10: cristian.gallego543 | D10: 3 | E10: CODIGO PS-F-03 | F10: 2025-09-09 11:21:05.185376 | G10: KPI | H10: CrediOrbe Vigente | I10: valeria.giraldo913 | J10: 1113036406 | K10: YURI VALENCIA VALENCIA | L10: 3145950331 | M10: 45898 | N10: 3.45 | O10: LLAMADA TELEFÃ“NICATIPO AUDITORIA | P10: 0 | Q10: 0 | R10: 0 | S10: 0 | T10: 0 | U10: 0 | V10: 0 | W10: 0 | X10: 0 | Y10: 0 | Z10: 0 | AA10: 0 | AB10: 0 | AC10: 0 | AD10: 0 | AE10: 0 | AF10: 0 | AG10: 0 | AH10: 0 | AI10: 0 | AJ10: 3.45 | AK10: 0 | AL10: 0 | AM10: 0 | AN10: 0 | AO10: 0 | AP10: 0 | AQ10: 0 | AR10: 0 | AS10: =SUMIF(P10:AR10,3.45) -> 3.45
A11: EMPRESARIAL VIGENTE | B11: DIAGNÓSTICO | C11: cristian.gallego543 | D11: 3 | E11: CODIGO PS-F-03 | F11: 2025-09-08 16:43:21.791706 | G11: KPI | H11: CrediOrbe Vigente | I11: valeria.giraldo913 | J11: 1879815 | K11: MARIA ELSI LEYTON GAITAN | L11: 3222889204 | M11: 45894 | N11: 24.15 | O11: LLAMADA TELEFÃ“NICATIPO AUDITORIA | P11: 0 | Q11: 3.45 | R11: 3.45 | S11: 3.45 | T11: 3.45 | U11: 3.45 | V11: 3.45 | W11: 0 | X11: 0 | Y11: 0 | Z11: 0 | AA11: 0 | AB11: 0 | AC11: 0 | AD11: 0 | AE11: 3.45 | AF11: 0 | AG11: 0 | AH11: 0 | AI11: 0 | AJ11: 0 | AK11: 0 | AL11: 0 | AM11: 0 | AN11: 0 | AO11: 0 | AP11: 0 | AQ11: 0 | AR11: 0 | AS11: =SUMIF(P11:AR11,3.45) -> 24.15
A12: EMPRESARIAL VIGENTE | B12: DIAGNÓSTICO | C12: cristian.gallego543 | D12: 3 | E12: CODIGO PS-F-03 | F12: 2025-09-08 14:18:49.824369 | G12: KPI | H12: CrediOrbe Vigente | I12: valeria.giraldo913 | J12: 1862295 | K12: MARLENY MONTIEL PRADA | L12: 3195715429 | M12: 45884 | N12: 13.8 | O12: LLAMADA TELEFÃ“NICATIPO AUDITORIA | P12: 0 | Q12: 3.45 | R12: 0 | S12: 3.45 | T12: 0 | U12: 3.45 | V12: 3.45 | W12: 0 | X12: 0 | Y12: 0 | Z12: 0 | AA12: 0 | AB12: 0 | AC12: 0 | AD12: 0 | AE12: 0 | AF12: 0 | AG12: 0 | AH12: 0 | AI12: 0 | AJ12: 0 | AK12: 0 | AL12: 0 | AM12: 0 | AN12: 0 | AO12: 0 | AP12: 0 | AQ12: 0 | AR12: 0 | AS12: =SUMIF(P12:AR12,3.45) -> 13.8
A13: EMPRESARIAL VIGENTE | B13: DIAGNÓSTICO | C13: VALERIA GIRALDO | O13: SUBTOTAL | P13: =SUM(P8:P12) -> 6.9 | Q13: =SUM(Q8:Q12) -> 10.35 | R13: =SUM(R8:R12) -> 3.45 | S13: =SUM(S8:S12) -> 6.9 | T13: =SUM(T8:T12) -> 3.45 | U13: =SUM(U8:U12) -> 6.9 | V13: =SUM(V8:V12) -> 6.9 | W13: =SUM(W8:W12) -> 3.45 | ... AS13: =SUM(AS8:AS12) -> 65.55
A14: EMPRESARIAL VIGENTE | B14: DIAGNÓSTICO | C14: cristian.gallego543 | D14: 3 | E14: CODIGO PS-F-03 | F14: 2025-09-15 17:35:54.879775 | G14: KPI | H14: CrediOrbe Vigente | I14: yiseth.cifuentes484 | J14: 2294322 | K14: LUIS FRANCISCO GARZON RAMOS | L14: 3122010235 | M14: 45897 | N14: 41.4 | O14: LLAMADA TELEFÃ“NICATIPO AUDITORIA | P14: 0 | Q14: 3.45 | R14: 3.45 | S14: 3.45 | T14: 3.45 | U14: 3.45 | V14: 3.45 | W14: 0 | X14: 0 | Y14: 0 | Z14: 3.45 | AA14: 3.45 | AB14: 0 | AC14: 3.45 | AD14: 0 | AE14: 3.45 | AF14: 3.45 | AG14: 0 | AH14: 0 | AI14: 0 | AJ14: 3.45 | AK14: 0 | AL14: 0 | AM14: 0 | AN14: 0 | AO14: 0 | AP14: 0 | AQ14: 0 | AR14: 0 | AS14: =SUMIF(P14:AR14,3.45) -> 41.4
A15: EMPRESARIAL VIGENTE | B15: DIAGNÓSTICO | C15: cristian.gallego543 | D15: 3 | E15: CODIGO PS-F-03 | F15: 2025-09-15 15:27:07.624594 | G15: KPI | H15: CrediOrbe Vigente | I15: yiseth.cifuentes484 | J15: 2289441 | K15: NORIA CAMAYO CAMPO | L15: 3102103741 | M15: 45894 | N15: 27.6 | O15: LLAMADA TELEFÃ“NICATIPO AUDITORIA | P15: 0 | Q15: 0 | R15: 3.45 | S15: 3.45 | T15: 3.45 | U15: 3.45 | V15: 3.45 | W15: 0 | X15: 0 | Y15: 0 | Z15: 0 | AA15: 0 | AB15: 0 | AC15: 0 | AD15: 0 | AE15: 3.45 | AF15: 3.45 | AG15: 0 | AH15: 0 | AI15: 0 | AJ15: 3.45 | AK15: 0 | AL15: 0 | AM15: 0 | AN15: 0 | AO15: 0 | AP15: 0 | AQ15: 0 | AR15: 0 | AS15: =SUMIF(P15:AR15,3.45) -> 27.6
A16: EMPRESARIAL VIGENTE | B16: DIAGNÓSTICO | C16: cristian.gallego543 | D16: 3 | E16: CODIGO PS-F-03 | F16: 2025-09-15 13:50:44.289667 | G16: KPI | H16: CrediOrbe Vigente | I16: yiseth.cifuentes484 | J16: 1869928 | K16: EDGAR ANDRES GOMEZ PICON | L16: 3016666239 | M16: 45906 | N16: 3.45 | O16: LLAMADA TELEFÃ“NICATIPO AUDITORIA | P16: 3.45 | Q16: 0 | R16: 0 | S16: 0 | T16: 0 | U16: 0 | V16: 0 | W16: 0 | X16: 0 | Y16: 0 | Z16: 0 | AA16: 0 | AB16: 0 | AC16: 0 | AD16: 0 | AE16: 0 | AF16: 0 | AG16: 0 | AH16: 0 | AI16: 0 | AJ16: 0 | AK16: 0 | AL16: 0 | AM16: 0 | AN16: 0 | AO16: 0 | AP16: 0 | AQ16: 0 | AR16: 0 | AS16: =SUMIF(P16:AR16,3.45) -> 3.45
A17: EMPRESARIAL VIGENTE | B17: DIAGNÓSTICO | C17: cristian.gallego543 | D17: 3 | E17: CODIGO PS-F-03 | F17: 2025-09-10 13:52:51.508716 | G17: KPI | H17: CrediOrbe Vigente | I17: yiseth.cifuentes484 | J17: 2160759 | K17: JORGE ARMANDO SANTANA SOTO | L17: 3202279425 | M17: 45895 | N17: 6.9 | O17: LLAMADA TELEFÃ“NICATIPO AUDITORIA | P17: 0 | Q17: 0 | R17: 3.45 | S17: 0 | T17: 0 | U17: 0 | V17: 0 | W17: 0 | X17: 0 | Y17: 0 | Z17: 0 | AA17: 0 | AB17: 0 | AC17: 0 | AD17: 0 | AE17: 0 | AF17: 3.45 | AG17: 0 | AH17: 0 | AI17: 0 | AJ17: 0 | AK17: 0 | AL17: 0 | AM17: 0 | AN17: 0 | AO17: 0 | AP17: 0 | AQ17: 0 | AR17: 0 | AS17: =SUMIF(P17:AR17,3.45) -> 6.9
A18: EMPRESARIAL VIGENTE | B18: DIAGNÓSTICO | C18: cristian.gallego543 | D18: 3 | E18: CODIGO PS-F-03 | F18: 2025-09-10 11:57:53.944297 | G18: KPI | H18: CrediOrbe Vigente | I18: yiseth.cifuentes484 | J18: 2052224 | K18: MAYRA ALEJANDRA CORONADO TRUJILLO | L18: 3102103741 | M18: 45897 | N18: 10.35 | O18: LLAMADA TELEFÃ“NICATIPO AUDITORIA | P18: 0 | Q18: 0 | R18: 0 | S18: 0 | T18: 3.45 | U18: 3.45 | V18: 3.45 | W18: 0 | X18: 0 | Y18: 0 | Z18: 0 | AA18: 0 | AB18: 0 | AC18: 0 | AD18: 0 | AE18: 0 | AF18: 0 | AG18: 0 | AH18: 0 | AI18: 0 | AJ18: 0 | AK18: 0 | AL18: 0 | AM18: 0 | AN18: 0 | AO18: 0 | AP18: 0 | AQ18: 0 | AR18: 0 | AS18: =SUMIF(P18:AR18,3.45) -> 10.35
A19: EMPRESARIAL VIGENTE | B19: DIAGNÓSTICO | C19: YISETH CIFUENTES | O19: SUBTOTAL | P19: =SUM(P14:P18) -> 3.45 | Q19: =SUM(Q14:Q18) -> 3.45 | R19: =SUM(R14:R18) -> 10.35 | S19: =SUM(S14:S18) -> 6.9 | T19: =SUM(T14:T18) -> 10.35 | U19: =SUM(U14:U18) -> 10.35 | V19: =SUM(V14:V18) -> 10.35 | W19: =SUM(W14:W18) -> 0 | ... AS19: =SUM(AS14:AS18) -> 89.7
A20: EMPRESARIAL VIGENTE | B20: DIAGNÓSTICO | O20: TOTAL EQUIPO | P20: =SUM(P7,P13,P19) -> 10.35 | Q20: =SUM(Q7,Q13,Q19) -> 24.15 | R20: =SUM(R7,R13,R19) -> 13.8 | S20: =SUM(S7,S13,S19) -> 13.8 | T20: =SUM(T7,T13,T19) -> 27.6 | U20: =SUM(U7,U13,U19) -> 31.05 | V20: =SUM(V7,V13,V19) -> 34.5 | W20: =SUM(W7,W13,W19) -> 17.25 | ... AS20: =SUM(AS7,AS13,AS19) -> 248.4
A21: EMPRESARIAL VIGENTE | B21: MONITOREO 1 | C21: cristian.gallego543 | D21: 3 | E21: CODIGO PS-F-03 | F21: 2025-09-12 15:44:34.03636 | G21: KPI | H21: CrediOrbe Vigente | I21: cristian.cifuentes013 | J21: 2036644 | K21: YESICA CATHERINE BAUTISTA PALACIO | L21: 3188120410 | M21: 45903 | N21: 6.9 | O21: LLAMADA TELEFÃ“NICATIPO AUDITORIA | P21: 0 | Q21: 0 | R21: 0 | S21: 0 | T21: 0 | U21: 0 | V21: 0 | W21: 0 | X21: 0 | Y21: 0 | Z21: 0 | AA21: 0 | AB21: 0 | AC21: 0 | AD21: 0 | AE21: 0 | AF21: 0 | AG21: 0 | AH21: 0 | AI21: 0 | AJ21: 0 | AK21: 0 | AL21: 0 | AM21: 0 | AN21: 0 | AO21: 0 | AP21: 0 | AQ21: 0 | AR21: 0 | AS21: =SUMIF(P21:AR21,3.45) -> 0
A22: EMPRESARIAL VIGENTE | B22: MONITOREO 1 | C22: cristian.gallego543 | D22: 3 | E22: CODIGO PS-F-03 | F22: 2025-09-05 14:26:25.633078 | G22: KPI | H22: CrediOrbe Vigente | I22: cristian.cifuentes013 | J22: 2012501 | K22: Marelis yanilis orozco cabarcas | L22: 3124250477 | M22: 45895 | N22: 13.8 | O22: LLAMADA TELEFÃ“NICATIPO AUDITORIA | P22: 0 | Q22: 0 | R22: 0 | S22: 0 | T22: 0 | U22: 0 | V22: 0 | W22: 0 | X22: 0 | Y22: 0 | Z22: 0 | AA22: 0 | AB22: 0 | AC22: 0 | AD22: 0 | AE22: 0 | AF22: 0 | AG22: 0 | AH22: 0 | AI22: 0 | AJ22: 0 | AK22: 0 | AL22: 0 | AM22: 0 | AN22: 0 | AO22: 0 | AP22: 0 | AQ22: 0 | AR22: 0 | AS22: =SUMIF(P22:AR22,3.45) -> 0
A23: EMPRESARIAL VIGENTE | B23: MONITOREO 1 | C23: cristian.gallego543 | D23: 3 | E23: CODIGO PS-F-03 | F23: 2025-09-05 11:01:52.205482 | G23: KPI | H23: CrediOrbe Vigente | I23: cristian.cifuentes013 | J23: 1980561 | K23: YEIMY KATHERINE VALDELAMAR MARIN | L23: 3136765995 | M23: 45895 | N23: 20.7 | O23: LLAMADA TELEFÃ“NICATIPO AUDITORIA | P23: 0 | Q23: 0 | R23: 0 | S23: 0 | T23: 0 | U23: 0 | V23: 0 | W23: 0 | X23: 0 | Y23: 0 | Z23: 0 | AA23: 0 | AB23: 0 | AC23: 0 | AD23: 0 | AE23: 0 | AF23: 0 | AG23: 0 | AH23: 0 | AI23: 0 | AJ23: 0 | AK23: 0 | AL23: 0 | AM23: 0 | AN23: 0 | AO23: 0 | AP23: 0 | AQ23: 0 | AR23: 0 | AS23: =SUMIF(P23:AR23,3.45) -> 0
A24: EMPRESARIAL VIGENTE | B24: MONITOREO 1 | C24: cristian.gallego543 | D24: 3 | E24: CODIGO PS-F-03 | F24: 2025-09-05 10:16:55.792877 | G24: KPI | H24: CrediOrbe Vigente | I24: cristian.cifuentes013 | J24: 1912585 | L24: 3136730889 | M24: 45894 | N24: 27.6 | O24: LLAMADA TELEFÃ“NICATIPO AUDITORIA | P24: 0 | Q24: 0 | R24: 0 | S24: 0 | T24: 0 | U24: 0 | V24: 0 | W24: 0 | X24: 0 | Y24: 0 | Z24: 0 | AA24: 0 | AB24: 0 | AC24: 0 | AD24: 0 | AE24: 0 | AF24: 0 | AG24: 0 | AH24: 0 | AI24: 0 | AJ24: 0 | AK24: 0 | AL24: 0 | AM24: 0 | AN24: 0 | AO24: 0 | AP24: 0 | AQ24: 0 | AR24: 0 | AS24: =SUMIF(P24:AR24,3.45) -> 0
A25: EMPRESARIAL VIGENTE | B25: MONITOREO 1 | C25: cristian.gallego543 | D25: 3 | E25: CODIGO PS-F-03 | F25: 2025-09-04 17:02:30.718431 | G25: KPI | H25: CrediOrbe Vigente | I25: cristian.cifuentes013 | J25: 1862296 | K25: MARLENY MONTIEL PRADA | L25: 3195715429 | M25: 45898 | N25: 24.15 | O25: LLAMADA TELEFÃ“NICATIPO AUDITORIA | P25: 0 | Q25: 0 | R25: 0 | S25: 0 | T25: 0 | U25: 0 | V25: 0 | W25: 0 | X25: 0 | Y25: 0 | Z25: 0 | AA25: 0 | AB25: 0 | AC25: 0 | AD25: 0 | AE25: 0 | AF25: 0 | AG25: 0 | AH25: 0 | AI25: 0 | AJ25: 0 | AK25: 0 | AL25: 0 | AM25: 0 | AN25: 0 | AO25: 0 | AP25: 0 | AQ25: 0 | AR25: 0 | AS25: =SUMIF(P25:AR25,3.45) -> 0
A26: EMPRESARIAL VIGENTE | B26: MONITOREO 1 | C26: CRISTIAN CIFUENTES | O26: SUBTOTAL | P26: =SUM(P21:P25) -> 0 | Q26: =SUM(Q21:Q25) -> 0 | R26: =SUM(R21:R25) -> 0 | S26: =SUM(S21:S25) -> 0 | T26: =SUM(T21:T25) -> 0 | U26: =SUM(U21:U25) -> 0 | V26: =SUM(V21:V25) -> 0 | W26: =SUM(W21:W25) -> 0 | ... AS26: =SUM(AS21:AS25) -> 0
A27: EMPRESARIAL VIGENTE | B27: MONITOREO 1 | C27: cristian.gallego543 | D27: 3 | E27: CODIGO PS-F-03 | F27: 2025-09-17 11:19:59.561569 | G27: KPI | H27: CrediOrbe Vigente | I27: valeria.giraldo913 | J27: 2116291 | K27: FELIPE DE JESUS GONZALEZ LOAIZA | L27: 3017616045 | M27: 45894 | N27: 13.8 | O27: LLAMADA TELEFÃ“NICATIPO AUDITORIA | P27: 0 | Q27: 0 | R27: 0 | S27: 0 | T27: 0 | U27: 0 | V27: 0 | W27: 0 | X27: 0 | Y27: 0 | Z27: 0 | AA27: 0 | AB27: 0 | AC27: 0 | AD27: 0 | AE27: 0 | AF27: 0 | AG27: 0 | AH27: 0 | AI27: 0 | AJ27: 0 | AK27: 0 | AL27: 0 | AM27: 0 | AN27: 0 | AO27: 0 | AP27: 0 | AQ27: 0 | AR27: 0 | AS27: =SUMIF(P27:AR27,3.45) -> 0
A28: EMPRESARIAL VIGENTE | B28: MONITOREO 1 | C28: cristian.gallego543 | D28: 3 | E28: CODIGO PS-F-03 | F28: 2025-09-17 09:45:07.882145 | G28: KPI | H28: CrediOrbe Vigente | I28: valeria.giraldo913 | J28: 2124205 | K28: MAYERLIN CASTILLO PERLAZA | L28: 3217239673 | M28: 45917 | N28: 10.35 | O28: LLAMADA TELEFÃ“NICATIPO AUDITORIA | P28: 0 | Q28: 0 | R28: 0 | S28: 0 | T28: 0 | U28: 0 | V28: 0 | W28: 0 | X28: 0 | Y28: 0 | Z28: 0 | AA28: 0 | AB28: 0 | AC28: 0 | AD28: 0 | AE28: 0 | AF28: 0 | AG28: 0 | AH28: 0 | AI28: 0 | AJ28: 0 | AK28: 0 | AL28: 0 | AM28: 0 | AN28: 0 | AO28: 0 | AP28: 0 | AQ28: 0 | AR28: 0 | AS28: =SUMIF(P28:AR28,3.45) -> 0
A29: EMPRESARIAL VIGENTE | B29: MONITOREO 1 | C29: cristian.gallego543 | D29: 3 | E29: CODIGO PS-F-03 | F29: 2025-09-09 11:21:05.185376 | G29: KPI | H29: CrediOrbe Vigente | I29: valeria.giraldo913 | J29: 1113036406 | K29: YURI VALENCIA VALENCIA | L29: 3145950331 | M29: 45898 | N29: 3.45 | O29: LLAMADA TELEFÃ“NICATIPO AUDITORIA | P29: 0 | Q29: 0 | R29: 0 | S29: 0 | T29: 0 | U29: 0 | V29: 0 | W29: 0 | X29: 0 | Y29: 0 | Z29: 0 | AA29: 0 | AB29: 0 | AC29: 0 | AD29: 0 | AE29: 0 | AF29: 0 | AG29: 0 | AH29: 0 | AI29: 0 | AJ29: 0 | AK29: 0 | AL29: 0 | AM29: 0 | AN29: 0 | AO29: 0 | AP29: 0 | AQ29: 0 | AR29: 0 | AS29: =SUMIF(P29:AR29,3.45) -> 0
A30: EMPRESARIAL VIGENTE | B30: MONITOREO 1 | C30: cristian.gallego543 | D30: 3 | E30: CODIGO PS-F-03 | F30: 2025-09-08 16:43:21.791706 | G30: KPI | H30: CrediOrbe Vigente | I30: valeria.giraldo913 | J30: 1879815 | K30: MARIA ELSI LEYTON GAITAN | L30: 3222889204 | M30: 45894 | N30: 24.15 | O30: LLAMADA TELEFÃ“NICATIPO AUDITORIA | P30: 0 | Q30: 0 | R30: 0 | S30: 0 | T30: 0 | U30: 0 | V30: 0 | W30: 0 | X30: 0 | Y30: 0 | Z30: 0 | AA30: 0 | AB30: 0 | AC30: 0 | AD30: 0 | AE30: 0 | AF30: 0 | AG30: 0 | AH30: 0 | AI30: 0 | AJ30: 0 | AK30: 0 | AL30: 0 | AM30: 0 | AN30: 0 | AO30: 0 | AP30: 0 | AQ30: 0 | AR30: 0 | AS30: =SUMIF(P30:AR30,3.45) -> 0
A31: EMPRESARIAL VIGENTE | B31: MONITOREO 1 | C31: cristian.gallego543 | D31: 3 | E31: CODIGO PS-F-03 | F31: 2025-09-08 14:18:49.824369 | G31: KPI | H31: CrediOrbe Vigente | I31: valeria.giraldo913 | J31: 1862295 | K31: MARLENY MONTIEL PRADA | L31: 3195715429 | M31: 45884 | N31: 13.8 | O31: LLAMADA TELEFÃ“NICATIPO AUDITORIA | P31: 0 | Q31: 0 | R31: 0 | S31: 0 | T31: 0 | U31: 0 | V31: 0 | W31: 0 | X31: 0 | Y31: 0 | Z31: 0 | AA31: 0 | AB31: 0 | AC31: 0 | AD31: 0 | AE31: 0 | AF31: 0 | AG31: 0 | AH31: 0 | AI31: 0 | AJ31: 0 | AK31: 0 | AL31: 0 | AM31: 0 | AN31: 0 | AO31: 0 | AP31: 0 | AQ31: 0 | AR31: 0 | AS31: =SUMIF(P31:AR31,3.45) -> 0
A32: EMPRESARIAL VIGENTE | B32: MONITOREO 1 | C32: VALERIA GIRALDO | O32: SUBTOTAL | P32: =SUM(P27:P31) -> 0 | Q32: =SUM(Q27:Q31) -> 0 | R32: =SUM(R27:R31) -> 0 | S32: =SUM(S27:S31) -> 0 | T32: =SUM(T27:T31) -> 0 | U32: =SUM(U27:U31) -> 0 | V32: =SUM(V27:V31) -> 0 | W32: =SUM(W27:W31) -> 0 | ... AS32: =SUM(AS27:AS31) -> 0
A33: EMPRESARIAL VIGENTE | B33: MONITOREO 1 | C33: cristian.gallego543 | D33: 3 | E33: CODIGO PS-F-03 | F33: 2025-09-15 17:35:54.879775 | G33: KPI | H33: CrediOrbe Vigente | I33: yiseth.cifuentes484 | J33: 2294322 | K33: LUIS FRANCISCO GARZON RAMOS | L33: 3122010235 | M33: 45897 | N33: 41.4 | O33: LLAMADA TELEFÃ“NICATIPO AUDITORIA | P33: 0 | Q33: 0 | R33: 0 | S33: 0 | T33: 0 | U33: 0 | V33: 0 | W33: 0 | X33: 0 | Y33: 0 | Z33: 0 | AA33: 0 | AB33: 0 | AC33: 0 | AD33: 0 | AE33: 0 | AF33: 0 | AG33: 0 | AH33: 0 | AI33: 0 | AJ33: 0 | AK33: 0 | AL33: 0 | AM33: 0 | AN33: 0 | AO33: 0 | AP33: 0 | AQ33: 0 | AR33: 0 | AS33: =SUMIF(P33:AR33,3.45) -> 0
A34: EMPRESARIAL VIGENTE | B34: MONITOREO 1 | C34: cristian.gallego543 | D34: 3 | E34: CODIGO PS-F-03 | F34: 2025-09-15 15:27:07.624594 | G34: KPI | H34: CrediOrbe Vigente | I34: yiseth.cifuentes484 | J34: 2289441 | K34: NORIA CAMAYO CAMPO | L34: 3102103741 | M34: 45894 | N34: 27.6 | O34: LLAMADA TELEFÃ“NICATIPO AUDITORIA | P34: 0 | Q34: 0 | R34: 0 | S34: 0 | T34: 0 | U34: 0 | V34: 0 | W34: 0 | X34: 0 | Y34: 0 | Z34: 0 | AA34: 0 | AB34: 0 | AC34: 0 | AD34: 0 | AE34: 0 | AF34: 0 | AG34: 0 | AH34: 0 | AI34: 0 | AJ34: 0 | AK34: 0 | AL34: 0 | AM34: 0 | AN34: 0 | AO34: 0 | AP34: 0 | AQ34: 0 | AR34: 0 | AS34: =SUMIF(P34:AR34,3.45) -> 0
A35: EMPRESARIAL VIGENTE | B35: MONITOREO 1 | C35: cristian.gallego543 | D35: 3 | E35: CODIGO PS-F-03 | F35: 2025-09-15 13:50:44.289667 | G35: KPI | H35: CrediOrbe Vigente | I35: yiseth.cifuentes484 | J35: 1869928 | K35: EDGAR ANDRES GOMEZ PICON | L35: 3016666239 | M35: 45906 | N35: 3.45 | O35: LLAMADA TELEFÃ“NICATIPO AUDITORIA | P35: 0 | Q35: 0 | R35: 0 | S35: 0 | T35: 0 | U35: 0 | V35: 0 | W35: 0 | X35: 0 | Y35: 0 | Z35: 0 | AA35: 0 | AB35: 0 | AC35: 0 | AD35: 0 | AE35: 0 | AF35: 0 | AG35: 0 | AH35: 0 | AI35: 0 | AJ35: 0 | AK35: 0 | AL35: 0 | AM35: 0 | AN35: 0 | AO35: 0 | AP35: 0 | AQ35: 0 | AR35: 0 | AS35: =SUMIF(P35:AR35,3.45) -> 0
A36: EMPRESARIAL VIGENTE | B36: MONITOREO 1 | C36: cristian.gallego543 | D36: 3 | E36: CODIGO PS-F-03 | F36: 2025-09-10 13:52:51.508716 | G36: KPI | H36: CrediOrbe Vigente | I36: yiseth.cifuentes484 | J36: 2160759 | K36: JORGE ARMANDO SANTANA SOTO | L36: 3202279425 | M36: 45895 | N36: 6.9 | O36: LLAMADA TELEFÃ“NICATIPO AUDITORIA | P36: 0 | Q36: 0 | R36: 0 | S36: 0 | T36: 0 | U36: 0 | V36: 0 | W36: 0 | X36: 0 | Y36: 0 | Z36: 0 | AA36: 0 | AB36: 0 | AC36: 0 | AD36: 0 | AE36: 0 | AF36: 0 | AG36: 0 | AH36: 0 | AI36: 0 | AJ36: 0 | AK36: 0 | AL36: 0 | AM36: 0 | AN36: 0 | AO36: 0 | AP36: 0 | AQ36: 0 | AR36: 0 | AS36: =SUMIF(P36:AR36,3.45) -> 0
A37: EMPRESARIAL VIGENTE | B37: MONITOREO 1 | C37: cristian.gallego543 | D37: 3 | E37: CODIGO PS-F-03 | F37: 2025-09-10 11:57:53.944297 | G37: KPI | H37: CrediOrbe Vigente | I37: yiseth.cifuentes484 | J37: 2052224 | K37: MAYRA ALEJANDRA CORONADO TRUJILLO | L37: 3102103741 | M37: 45897 | N37: 10.35 | O37: LLAMADA TELEFÃ“NICATIPO AUDITORIA | P37: 0 | Q37: 0 | R37: 0 | S37: 0 | T37: 0 | U37: 0 | V37: 0 | W37: 0 | X37: 0 | Y37: 0 | Z37: 0 | AA37: 0 | AB37: 0 | AC37: 0 | AD37: 0 | AE37: 0 | AF37: 0 | AG37: 0 | AH37: 0 | AI37: 0 | AJ37: 0 | AK37: 0 | AL37: 0 | AM37: 0 | AN37: 0 | AO37: 0 | AP37: 0 | AQ37: 0 | AR37: 0 | AS37: =SUMIF(P37:AR37,3.45) -> 0
A38: EMPRESARIAL VIGENTE | B38: MONITOREO 1 | C38: YISETH CIFUENTES | O38: SUBTOTAL | P38: =SUM(P33:P37) -> 0 | Q38: =SUM(Q33:Q37) -> 0 | R38: =SUM(R33:R37) -> 0 | S38: =SUM(S33:S37) -> 0 | T38: =SUM(T33:T37) -> 0 | U38: =SUM(U33:U37) -> 0 | V38: =SUM(V33:V37) -> 0 | W38: =SUM(W33:W37) -> 0 | ... AS38: =SUM(AS33:AS37) -> 0
A39: EMPRESARIAL VIGENTE | B39: MONITOREO 1 | O39: TOTAL EQUIPO | P39: =SUM(P26,P32,P38) -> 0 | Q39: =SUM(Q26,Q32,Q38) -> 0 | R39: =SUM(R26,R32,R38) -> 0 | S39: =SUM(S26,S32,S38) -> 0 | T39: =SUM(T26,T32,T38) -> 0 | U39: =SUM(U26,U32,U38) -> 0 | V39: =SUM(V26,V32,V38) -> 0 | W39: =SUM(W26,W32,W38) -> 0 | ... AS39: =SUM(AS26,AS32,AS38) -> 0
A40: EMPRESARIAL VIGENTE | B40: MONITOREO 2 | C40: cristian.gallego543 | D40: 3 | E40: CODIGO PS-F-03 | F40: 2025-09-12 15:44:34.03636 | G40: KPI | H40: CrediOrbe Vigente | I40: cristian.cifuentes013 | J40: 2036644 | K40: YESICA CATHERINE BAUTISTA PALACIO | L40: 3188120410 | M40: 45903 | N40: 6.9 | O40: LLAMADA TELEFÃ“NICATIPO AUDITORIA | P40: 0 | Q40: 0 | R40: 0 | S40: 0 | T40: 0 | U40: 0 | V40: 0 | W40: 0 | X40: 0 | Y40: 0 | Z40: 0 | AA40: 0 | AB40: 0 | AC40: 0 | AD40: 0 | AE40: 0 | AF40: 0 | AG40: 0 | AH40: 0 | AI40: 0 | AJ40: 0 | AK40: 0 | AL40: 0 | AM40: 0 | AN40: 0 | AO40: 0 | AP40: 0 | AQ40: 0 | AR40: 0 | AS40: =SUMIF(P40:AR40,3.45) -> 0
...

Sheet CUARTILAMIENTO
A1: CUARTILAMIENTO POR EQUIPO | E1: CUARTILAMIENTO DIAGNOSTICO
A2: CUARTIL | B2: TIPO | C2: PUNTAJE | E2: RAC | F2: PUNTAJE | G2: PUNTAJE | H2: CUARTIL
A3: Q1 | B3: ALTO DESEMPEÑO | C3: =TEXT($C$33,"0") & "-" & TEXT($C$34,"0") -> 0-94 | E3: CRISTIAN CIFUENTES | F3: =DIAGNÓSTICO!AS7 -> 93.15 | G3: =F3*100 -> 9315 | H3: =IF(G3<$D$34,$A$16,IF(G3<$D$36,$A$17,IF(G3<$D$38,$A$18,IF(G3<$D$40,$A$19,0)))) -> 0
A4: Q2 | B4: MEDIO DESEMPEÑO | C4: =TEXT($C$35,"0") & "-" & TEXT($C$36,"0") -> 95-188 | E4: VALERIA GIRALDO | F4: =DIAGNÓSTICO!AS13 -> 65.55 | G4: =F4*100 -> 6555 | H4: =IF(G4<$D$34,$A$16,IF(G4<$D$36,$A$17,IF(G4<$D$38,$A$18,IF(G4<$D$40,$A$19,0)))) -> 0
A5: Q3 | B5: BAJO DESEMPEÑO | C5: =TEXT($C$37,"0") & "-" & TEXT($C$38,"0") -> 189-281 | E5: YISETH CIFUENTES | F5: =DIAGNÓSTICO!AS19 -> 89.7 | G5: =F5*100 -> 8970 | H5: =IF(G5<$D$34,$A$16,IF(G5<$D$36,$A$17,IF(G5<$D$38,$A$18,IF(G5<$D$40,$A$19,0)))) -> 0
A6: Q4 | B6: DEFICIENTE DESEMPEÑO | C6: =TEXT($C$39,"0") & "-" & TEXT($C$40,"0") -> 282-375 | E6: SUMA EQUIPO | F6: =SUM(F3:F5) -> 248.4 | G6: =SUM(G3:G5) -> 24840 | H6: =IF(G6<C34,A3,IF(G6<C36,A4,IF(G6<C38,A5,IF(G6<C40,A6,0)))) -> 0
E7: CUARTILAMIENTO MONITOREO 1
E8: RAC | F8: PUNTAJE | G8: PUNTAJE | H8: CUARTIL
E9: CRISTIAN CIFUENTES | F9: =DIAGNÓSTICO!AS26 -> 0 | G9: =F9*100 -> 0 | H9: =IF(G9<$D$34,$A$16,IF(G9<$D$36,$A$17,IF(G9<$D$38,$A$18,IF(G9<$D$40,$A$19,0)))) -> Q1
E10: VALERIA GIRALDO | F10: =DIAGNÓSTICO!AS32 -> 0 | G10: =F10*100 -> 0 | H10: =IF(G10<$D$34,$A$16,IF(G10<$D$36,$A$17,IF(G10<$D$38,$A$18,IF(G10<$D$40,$A$19,0)))) -> Q1
E11: YISETH CIFUENTES | F11: =DIAGNÓSTICO!AS38 -> 0 | G11: =F11*100 -> 0 | H11: =IF(G11<$D$34,$A$16,IF(G11<$D$36,$A$17,IF(G11<$D$38,$A$18,IF(G11<$D$40,$A$19,0)))) -> Q1
E12: SUMA EQUIPO | F12: =SUM(F9:F11) -> 0 | G12: =SUM(G9:G11) -> 0 | H12: =IF(G12<C40,A9,IF(G12<C42,A10,IF(G12<C44,A11,IF(G12<C46,A12,0)))) -> 0
E13: CUARTILAMIENTO MONITOREO 2
A14: CUARTILAMIENTO POR EJECUTIVO | E14: RAC | F14: PUNTAJE | G14: PUNTAJE | H14: CUARTIL
A15: CUARTIL | B15: TIPO | C15: PUNTAJE | E15: CRISTIAN CIFUENTES | F15: =DIAGNÓSTICO!AS45 -> 0 | G15: =F15*100 -> 0 | H15: =IF(G15<$D$34,$A$16,IF(G15<$D$36,$A$17,IF(G15<$D$38,$A$18,IF(G15<$D$40,$A$19,0)))) -> Q1
A16: Q1 | B16: ALTO DESEMPEÑO | C16: =TEXT(D33,"0") & "-" & TEXT(D34,"0") -> 0-31 | E16: VALERIA GIRALDO | F16: =DIAGNÓSTICO!AS51 -> 0 | G16: =F16*100 -> 0 | H16: =IF(G16<$D$34,$A$16,IF(G16<$D$36,$A$17,IF(G16<$D$38,$A$18,IF(G16<$D$40,$A$19,0)))) -> Q1
A17: Q2 | B17: MEDIO DESEMPEÑO | C17: =TEXT(D35,"0") & "-" & TEXT(D36,"0") -> 32-63 | E17: YISETH CIFUENTES | F17: =DIAGNÓSTICO!AS57 -> 0 | G17: =F17*100 -> 0 | H17: =IF(G17<$D$34,$A$16,IF(G17<$D$36,$A$17,IF(G17<$D$38,$A$18,IF(G17<$D$40,$A$19,0)))) -> Q1
A18: Q3 | B18: BAJO DESEMPEÑO | C18: =TEXT(D37,"0") & "-" & TEXT(D38,"0") -> 64-94 | E18: SUMA EQUIPO | F18: =SUM(F15:F17) -> 0 | G18: =SUM(G15:G17) -> 0 | H18: =IF(G18<C46,A15,IF(G18<C48,A16,IF(G18<C50,A17,IF(G18<C52,A18,0)))) -> 0
A19: Q4 | B19: DEFICIENTE DESEMPEÑO | C19: =TEXT(D39,"0") & "-" & TEXT(D40,"0") -> 95-125 | E19: CUARTILAMIENTO MONITOREO 3
E20: RAC | F20: PUNTAJE | G20: PUNTAJE | H20: CUARTIL
E21: CRISTIAN CIFUENTES | F21: =DIAGNÓSTICO!AS64 -> 0 | G21: =F21*100 -> 0 | H21: =IF(G21<$D$34,$A$16,IF(G21<$D$36,$A$17,IF(G21<$D$38,$A$18,IF(G21<$D$40,$A$19,0)))) -> Q1
B22: CÁLCULO | C22: CANTIDAD | E22: VALERIA GIRALDO | F22: =DIAGNÓSTICO!AS70 -> 0 | G22: =F22*100 -> 0 | H22: =IF(G22<$D$34,$A$16,IF(G22<$D$36,$A$17,IF(G22<$D$38,$A$18,IF(G22<$D$40,$A$19,0)))) -> Q1
B23: AGENTES | C23: 3 | E23: YISETH CIFUENTES | F23: =DIAGNÓSTICO!AS76 -> 0 | G23: =F23*100 -> 0 | H23: =IF(G23<$D$34,$A$16,IF(G23<$D$36,$A$17,IF(G23<$D$38,$A$18,IF(G23<$D$40,$A$19,0)))) -> Q1
B24: CANTIDAD DE VARIABLES | C24: 29 | E24: SUMA EQUIPO | F24: =SUM(F21:F23) -> 0 | G24: =SUM(G21:G23) -> 0 | H24: =IF(G24<C52,A21,IF(G24<C54,A22,IF(G24<C56,A23,IF(G24<C58,A24,0)))) -> 0
B25: NÚMERO DE MUESTRAS | C25: =COUNTA(DIAGNÓSTICO!B8:B12) -> 5 | E25: CUARTILAMIENTO MONITOREO 4
B26: PESO DE CADA VARIABLE | C26: 3.45 | E26: RAC | F26: PUNTAJE | G26: PUNTAJE | H26: CUARTIL
B27: SUMA TOTAL VARIABLES | C27: =C23*C24*C25*C26 -> 1500.75 | E27: CRISTIAN CIFUENTES | F27: =DIAGNÓSTICO!AS83 -> 0 | G27: =F27*100 -> 0 | H27: =IF(G27<$D$34,$A$16,IF(G27<$D$36,$A$17,IF(G27<$D$38,$A$18,IF(G27<$D$40,$A$19,0)))) -> Q1
B28: Q4 EQUIPO | C28: =C27/4 -> 375.1875 | E28: VALERIA GIRALDO | F28: =DIAGNÓSTICO!AS89 -> 0 | G28: =F28*100 -> 0 | H28: =IF(G28<$D$34,$A$16,IF(G28<$D$36,$A$17,IF(G28<$D$38,$A$18,IF(G28<$D$40,$A$19,0)))) -> Q1
B29: Q1 EQUIPO | C29: =C28/4 -> 93.796875 | E29: YISETH CIFUENTES | F29: =DIAGNÓSTICO!AS95 -> 0 | G29: =F29*100 -> 0 | H29: =IF(G29<$D$34,$A$16,IF(G29<$D$36,$A$17,IF(G29<$D$38,$A$18,IF(G29<$D$40,$A$19,0)))) -> Q1
B30: Q4 AGENTE | C30: =C28/3 -> 125.0625 | E30: SUMA EQUIPO | F30: =SUM(F27:F29) -> 0 | G30: =SUM(G27:G29) -> 0 | H30: =IF(G30<C58,A27,IF(G30<C60,A28,IF(G30<C62,A29,IF(G30<C64,A30,0)))) -> 0
B31: Q1 AGENTE | C31: =C30/4 -> 31.265625
C32: - | D32: -
C33: 0 | D33: 0
C34: =C28/4 -> 93.796875 | D34: 31.265625
C35: =C34+1 -> 94.796875 | D35: =D34+1 -> 32.265625
C36: =C34+C34 -> 187.59375 | D36: =D34+D34 -> 62.53125
C37: =C36+1 -> 188.59375 | D37: =D36+1 -> 63.53125
C38: =C36+C34 -> 281.39062 | D38: =D36+D34 -> 93.796875
C39: =C38+1 -> 282.39062 | D39: =D38+1 -> 94.796875
C40: =C38+C34 -> 375.1875 | D40: =D38+D34 -> 125.0625

Sheet PARTITURA
A1: PORTAFOLIO | B1: FECHA | C1: SEGMENTO | D1: TIPO DE AUDITORÍA | E1: VARIABLE | F1: CALIFICACIÓN | G1: PESO | H1: IMPACTO TOTAL | I1: RESULTADO ESPERADO | J1: ESTADO | L1: SE MANTIENE | M1: MEJORA | N1: EMPEORA
A2: EMPRESARIAL ACTIVA | B2: 45917 | C2: ATENCIÓN TELEFÓNICA | D2: DIAGNÓSTICO | E2: PresentaciÃ³n, | F2: {=TRANSPOSE(DIAGNÓSTICO!P20:AR20)} -> 10.35 | G2: =IFERROR((F2/$F$31),0) -> 0.041666667 | H2: =((F2)-(F2/4)) -> 7.7625 | I2: =F2-H2 -> 2.5875
A3: EMPRESARIAL ACTIVA | B3: 45917 | C3: ATENCIÓN TELEFÓNICA | D3: DIAGNÓSTICO | E3: Explica el motivo de la llamada de forma clara y rÃ¡pida, | F3: 24.15 | G3: =IFERROR((F3/$F$31),0) -> 0.097222222 | H3: =((F3)-(F3/4)) -> 18.1125 | I3: =F3-H3 -> 6.0375
A4: EMPRESARIAL ACTIVA | B4: 45917 | C4: ATENCIÓN TELEFÓNICA | D4: DIAGNÓSTICO | E4: Escucha Activa, | F4: 13.8 | G4: =IFERROR((F4/$F$31),0) -> 0.055555556 | H4: =((F4)-(F4/4)) -> 10.35 | I4: =F4-H4 -> 3.45
A5: EMPRESARIAL ACTIVA | B5: 45917 | C5: ATENCIÓN TELEFÓNICA | D5: DIAGNÓSTICO | E5: Preguntar, | F5: 13.8 | G5: =IFERROR((F5/$F$31),0) -> 0.055555556 | H5: =((F5)-(F5/4)) -> 10.35 | I5: =F5-H5 -> 3.45
A6: EMPRESARIAL ACTIVA | B6: 45917 | C6: ATENCIÓN TELEFÓNICA | D6: DIAGNÓSTICO | E6: Rebatir, | F6: 27.6 | G6: =IFERROR((F6/$F$31),0) -> 0.11111111 | H6: =((F6)-(F6/4)) -> 20.7 | I6: =F6-H6 -> 6.9
A7: EMPRESARIAL ACTIVA | B7: 45917 | C7: ATENCIÓN TELEFÓNICA | D7: DIAGNÓSTICO | E7: Vender, | F7: 31.05 | G7: =IFERROR((F7/$F$31),0) -> 0.125 | H7: =((F7)-(F7/4)) -> 23.2875 | I7: =F7-H7 -> 7.7625
A8: EMPRESARIAL ACTIVA | B8: 45917 | C8: ATENCIÓN TELEFÓNICA | D8: DIAGNÓSTICO | E8: Beneficios, | F8: 34.5 | G8: =IFERROR((F8/$F$31),0) -> 0.13888889 | H8: =((F8)-(F8/4)) -> 25.875 | I8: =F8-H8 -> 8.625
A9: EMPRESARIAL ACTIVA | B9: 45917 | C9: ATENCIÓN TELEFÓNICA | D9: DIAGNÓSTICO | E9: Cierre, | F9: 17.25 | G9: =IFERROR((F9/$F$31),0) -> 0.069444444 | H9: =((F9)-(F9/4)) -> 12.9375 | I9: =F9-H9 -> 4.3125
A10: EMPRESARIAL ACTIVA | B10: 45917 | C10: ATENCIÓN TELEFÓNICA | D10: DIAGNÓSTICO | E10: ActualizaciÃ³n de datos, | F10: 6.9 | G10: =IFERROR((F10/$F$31),0) -> 0.027777778 | H10: =((F10)-(F10/4)) -> 5.175 | I10: =F10-H10 -> 1.725
A11: EMPRESARIAL ACTIVA | B11: 45917 | C11: ATENCIÓN TELEFÓNICA | D11: DIAGNÓSTICO | E11: Despedida, | F11: 13.8 | G11: =IFERROR((F11/$F$31),0) -> 0.055555556 | H11: =((F11)-(F11/4)) -> 10.35 | I11: =F11-H11 -> 3.45
A12: EMPRESARIAL ACTIVA | B12: 45917 | C12: IMPECABILIDAD | D12: DIAGNÓSTICO | E12: Oferta, | F12: 6.9 | G12: =IFERROR((F12/$F$31),0) -> 0.027777778 | H12: =((F12)-(F12/4)) -> 5.175 | I12: =F12-H12 -> 1.725
A13: EMPRESARIAL ACTIVA | B13: 45917 | C13: IMPECABILIDAD | D13: DIAGNÓSTICO | E13: Conocimiento Del Producto | F13: 3.45 | G13: =IFERROR((F13/$F$31),0) -> 0.013888889 | H13: =((F13)-(F13/4)) -> 2.5875 | I13: =F13-H13 -> 0.8625
A14: EMPRESARIAL ACTIVA | B14: 45917 | C14: IMPECABILIDAD | D14: DIAGNÓSTICO | E14: ModulaciÃ³n | F14: 0 | G14: =IFERROR((F14/$F$31),0) -> 0 | H14: =((F14)-(F14/4)) -> 0 | I14: =F14-H14 -> 0
... A30: EMPRESARIAL ACTIVA | B30: 45917 | C30: METODOLOGÍA DE GESTIÓN | D30: DIAGNÓSTICO | E30: Protocolo De GestiÃ³n | F30: 3.45 | G30: =IFERROR((F30/$F$31),0) -> 0.013888889 | H30: =((F30)-(F30/4)) -> 2.5875 | I30: =F30-H30 -> 0.8625
A31: EMPRESARIAL ACTIVA | B31: 45917 | C31: TOTAL | D31: TOTAL DIAGNÓSTICO | E31: TOTAL | F31: =SUM(F2:F30) -> 248.4 | G31: =SUM(G2:G30) -> 1 | H31: =((F31)-(F31/4)) -> 186.3 | I31: =SUM(I2:I30) -> 62.1 | J31: EMPEORA
A32: EMPRESARIAL ACTIVA | C32: ATENCIÓN TELEFÓNICA | D32: MONITOREO 1 | E32: PresentaciÃ³n, | F32: {=TRANSPOSE(DIAGNÓSTICO!P39:AR39)} -> 0 | G32: =IFERROR((F32/$F$61),0) -> 0 | H32: =H2/4 -> 1.940625 | I32: =F2-H32 -> 8.409375 | J32: =IF(F32<=I32,$M$1,IF(F32=F2,$L$1,IF(F32>F2,$N$1,0))) -> MEJORA
A33: EMPRESARIAL ACTIVA | C33: ATENCIÓN TELEFÓNICA | D33: MONITOREO 1 | E33: Explica el motivo de la llamada de forma clara y rÃ¡pida, | F33: 0 | G33: =IFERROR((F33/$F$61),0) -> 0 | H33: =H3/4 -> 4.528125 | I33: =F3-H33 -> 19.621875 | J33: =IF(F33<=I33,$M$1,IF(F33=F3,$L$1,IF(F33>F3,$N$1,0))) -> MEJORA
A34: EMPRESARIAL ACTIVA | C34: ATENCIÓN TELEFÓNICA | D34: MONITOREO 1 | E34: Escucha Activa, | F34: 0 | G34: =IFERROR((F34/$F$61),0) -> 0 | H34: =H4/4 -> 2.5875 | I34: =F4-H34 -> 11.2125 | J34: =IF(F34<=I34,$M$1,IF(F34=F4,$L$1,IF(F34>F4,$N$1,0))) -> MEJORA
A35: EMPRESARIAL ACTIVA | C35: ATENCIÓN TELEFÓNICA | D35: MONITOREO 1 | E35: Preguntar, | F35: 0 | G35: =IFERROR((F35/$F$61),0) -> 0 | H35: =H5/4 -> 2.5875 | I35: =F5-H35 -> 11.2125 | J35: =IF(F35<=I35,$M$1,IF(F35=F5,$L$1,IF(F35>F5,$N$1,0))) -> MEJORA
A36: EMPRESARIAL ACTIVA | C36: ATENCIÓN TELEFÓNICA | D36: MONITOREO 1 | E36: Rebatir, | F36: 0 | G36: =IFERROR((F36/$F$61),0) -> 0 | H36: =H6/4 -> 5.175 | I36: =F6-H36 -> 22.425 | J36: =IF(F36<=I36,$M$1,IF(F36=F6,$L$1,IF(F36>F6,$N$1,0))) -> MEJORA
A37: EMPRESARIAL ACTIVA | C37: ATENCIÓN TELEFÓNICA | D37: MONITOREO 1 | E37: Vender, | F37: 0 | G37: =IFERROR((F37/$F$61),0) -> 0 | H37: =H7/4 -> 5.821875 | I37: =F7-H37 -> 25.228125 | J37: =IF(F37<=I37,$M$1,IF(F37=F7,$L$1,IF(F37>F7,$N$1,0))) -> MEJORA
A38: EMPRESARIAL ACTIVA | C38: ATENCIÓN TELEFÓNICA | D38: MONITOREO 1 | E38: Beneficios, | F38: 0 | G38: =IFERROR((F38/$F$61),0) -> 0 | H38: =H8/4 -> 6.46875 | I38: =F8-H38 -> 28.03125 | J38: =IF(F38<=I38,$M$1,IF(F38=F8,$L$1,IF(F38>F8,$N$1,0))) -> MEJORA
A39: EMPRESARIAL ACTIVA | C39: ATENCIÓN TELEFÓNICA | D39: MONITOREO 1 | E39: Cierre, | F39: 0 | G39: =IFERROR((F39/$F$61),0) -> 0 | H39: =H9/4 -> 3.234375 | I39: =F9-H39 -> 14.015625 | J39: =IF(F39<=I39,$M$1,IF(F39=F9,$L$1,IF(F39>F9,$N$1,0))) -> MEJORA
A40: EMPRESARIAL ACTIVA | C40: ATENCIÓN TELEFÓNICA | D40: MONITOREO 1 | E40: ActualizaciÃ³n de datos, | F40: 0 | G40: =IFERROR((F40/$F$61),0) -> 0 | H40: =H10/4 -> 1.29375 | I40: =F10-H40 -> 5.60625 | J40: =IF(F40<=I40,$M$1,IF(F40=F10,$L$1,IF(F40>F10,$N$1,0))) -> MEJORA
A41: EMPRESARIAL ACTIVA | C41: ATENCIÓN TELEFÓNICA | D41: MONITOREO 1 | E41: Despedida, | F41: 0 | G41: =IFERROR((F41/$F$61),0) -> 0 | H41: =H11/4 -> 2.5875 | I41: =F11-H41 -> 11.2125 | J41: =IF(F41<=I41,$M$1,IF(F41=F11,$L$1,IF(F41>F11,$N$1,0))) -> MEJORA
A42: EMPRESARIAL ACTIVA | C42: IMPECABILIDAD | D42: MONITOREO 1 | E42: Oferta, | F42: 0 | G42: =IFERROR((F42/$F$61),0) -> 0 | H42: =H12/4 -> 1.29375 | I42: =F12-H42 -> 5.60625 | J42: =IF(F42<=I42,$M$1,IF(F42=F12,$L$1,IF(F42>F12,$N$1,0))) -> MEJORA
A43: EMPRESARIAL ACTIVA | C43: IMPECABILIDAD | D43: MONITOREO 1 | E43: Conocimiento Del Producto | F43: 0 | G43: =IFERROR((F43/$F$61),0) -> 0 | H43: =H13/4 -> 0.646875 | I43: =F13-H43 -> 2.803125 | J43: =IF(F43<=I43,$M$1,IF(F43=F13,$L$1,IF(F43>F13,$N$1,0))) -> MEJORA
A44: EMPRESARIAL ACTIVA | C44: IMPECABILIDAD | D44: MONITOREO 1 | E44: ModulaciÃ³n | F44: 0 | G44: =IFERROR((F44/$F$61),0) -> 0 | H44: =H14/4 -> 0 | I44: =F14-H44 -> 0 | J44: =IF(F44<=I44,$M$1,IF(F44=F14,$L$1,IF(F44>F14,$N$1,0))) -> MEJORA
... A60: EMPRESARIAL ACTIVA | C60: METODOLOGÍA DE GESTIÓN | D60: MONITOREO 1 | E60: Protocolo De GestiÃ³n | F60: 0 | G60: =IFERROR((F60/$F$61),0) -> 0 | H60: =H30/4 -> 0.646875 | I60: =F30-H60 -> 2.803125 | J60: =IF(F60<=I60,$M$1,IF(F60=F30,$L$1,IF(F60>F30,$N$1,0))) -> MEJORA
A61: EMPRESARIAL ACTIVA | C61: TOTAL | D61: TOTAL MONITOREO 1 | E61: TOTAL | F61: =SUM(F32:F60) -> 0 | G61: =SUM(G32:G60) -> 0 | H61: =SUM(H32:H60) -> 46.575 | I61: =F31-H61 -> 201.825 | J61: =IF(F61<=I61,$M$1,IF(F61=F31,$L$1,IF(F61>F31,$N$1,0))) -> MEJORA
A62: EMPRESARIAL ACTIVA | C62: ATENCIÓN TELEFÓNICA | D62: MONITOREO 2 | E62: PresentaciÃ³n, | F62: {=TRANSPOSE(DIAGNÓSTICO!P58:AR58)} -> 0 | G62: =IFERROR((F62/$F$91),0) -> 0 | H62: =H32 -> 1.940625 | I62: =((F2)-(H32+H62)) -> 6.46875 | J62: =IF(F62<=I62,$M$1,IF(F62=F32,$L$1,IF(F62>F32,$N$1,0))) -> MEJORA
A63: EMPRESARIAL ACTIVA | C63: ATENCIÓN TELEFÓNICA | D63: MONITOREO 2 | E63: Explica el motivo de la llamada de forma clara y rÃ¡pida, | F63: 0 | G63: =IFERROR((F63/$F$91),0) -> 0 | H63: =H33 -> 4.528125 | I63: =((F3)-(H33+H63)) -> 15.09375 | J63: =IF(F63<=I63,$M$1,IF(F63=F33,$L$1,IF(F63>F33,$N$1,0))) -> MEJORA
A64: EMPRESARIAL ACTIVA | C64: ATENCIÓN TELEFÓNICA | D64: MONITOREO 2 | E64: Escucha Activa, | F64: 0 | G64: =IFERROR((F64/$F$91),0) -> 0 | H64: =H34 -> 2.5875 | I64: =((F4)-(H34+H64)) -> 8.625 | J64: =IF(F64<=I64,$M$1,IF(F64=F34,$L$1,IF(F64>F34,$N$1,0))) -> MEJORA
A65: EMPRESARIAL ACTIVA | C65: ATENCIÓN TELEFÓNICA | D65: MONITOREO 2 | E65: Preguntar, | F65: 0 | G65: =IFERROR((F65/$F$91),0) -> 0 | H65: =H35 -> 2.5875 | I65: =((F5)-(H35+H65)) -> 8.625 | J65: =IF(F65<=I65,$M$1,IF(F65=F35,$L$1,IF(F65>F35,$N$1,0))) -> MEJORA
A66: EMPRESARIAL ACTIVA | C66: ATENCIÓN TELEFÓNICA | D66: MONITOREO 2 | E66: Rebatir, | F66: 0 | G66: =IFERROR((F66/$F$91),0) -> 0 | H66: =H36 -> 5.175 | I66: =((F6)-(H36+H66)) -> 17.25 | J66: =IF(F66<=I66,$M$1,IF(F66=F36,$L$1,IF(F66>F36,$N$1,0))) -> MEJORA
A67: EMPRESARIAL ACTIVA | C67: ATENCIÓN TELEFÓNICA | D67: MONITOREO 2 | E67: Vender, | F67: 0 | G67: =IFERROR((F67/$F$91),0) -> 0 | H67: =H37 -> 5.821875 | I67: =((F7)-(H37+H67)) -> 19.40625 | J67: =IF(F67<=I67,$M$1,IF(F67=F37,$L$1,IF(F67>F37,$N$1,0))) -> MEJORA
A68: EMPRESARIAL ACTIVA | C68: ATENCIÓN TELEFÓNICA | D68: MONITOREO 2 | E68: Beneficios, | F68: 0 | G68: =IFERROR((F68/$F$91),0) -> 0 | H68: =H38 -> 6.46875 | I68: =((F8)-(H38+H68)) -> 21.5625 | J68: =IF(F68<=I68,$M$1,IF(F68=F38,$L$1,IF(F68>F38,$N$1,0))) -> MEJORA
A69: EMPRESARIAL ACTIVA | C69: ATENCIÓN TELEFÓNICA | D69: MONITOREO 2 | E69: Cierre, | F69: 0 | G69: =IFERROR((F69/$F$91),0) -> 0 | H69: =H39 -> 3.234375 | I69: =((F9)-(H39+H69)) -> 10.78125 | J69: =IF(F69<=I69,$M$1,IF(F69=F39,$L$1,IF(F69>F39,$N$1,0))) -> MEJORA
A70: EMPRESARIAL ACTIVA | C70: ATENCIÓN TELEFÓNICA | D70: MONITOREO 2 | E70: ActualizaciÃ³n de datos, | F70: 0 | G70: =IFERROR((F70/$F$91),0) -> 0 | H70: =H40 -> 1.29375 | I70: =((F10)-(H40+H70)) -> 4.3125 | J70: =IF(F70<=I70,$M$1,IF(F70=F40,$L$1,IF(F70>F40,$N$1,0))) -> MEJORA
...

Sheet Hoja5
A1: SEGMENTO | B1: VARIABLE
A2: ATENCIÓN TELEFÓNICA | B2: PRESENTACIÓN
A3: ATENCIÓN TELEFÓNICA | B3: MOTIVO
A4: ATENCIÓN TELEFÓNICA | B4: ESCUCHA ACTIVA
A5: ATENCIÓN TELEFÓNICA | B5: PREGUNTAR
A6: ATENCIÓN TELEFÓNICA | B6: REBATIR
A7: ATENCIÓN TELEFÓNICA | B7: VENDER
A8: ATENCIÓN TELEFÓNICA | B8: BENEFICIOS
A9: ATENCIÓN TELEFÓNICA | B9: CIERRE
A10: ATENCIÓN TELEFÓNICA | B10: ACTUALIZACIÓN DE DATOS
A11: ATENCIÓN TELEFÓNICA | B11: DESPEDIDA
A12: IMPECABILIDAD | B12: ODERTA
... A31: TOTAL | B31: TOTAL

Sheet ESTRATIFICACIÓN
A1: PORTAFOLIO | B1: FECHA | C1: SEGMENTO | D1: TIPO DE AUDITORÍA | E1: KPI | F1: CALIFICACIÓN | G1: PESO | H1: IMPACTO TOTAL | I1: RESULTADO ESPERADO | J1: ESTADO | K1: SE MANTIENE | L1: MEJORA | M1: EMPEORA | N1: ESTRATO | O1: IMPACTO
A2: EMPRESARIAL ACTIVA | B2: 45917 | C2: ATENCIÓN TELEFÓNICA | D2: DIAGNÓSTICO | E2: Beneficios, | F2: 34.5 | G2: 0.13888889 | H2: IMPACTO TOTAL | I2: 8.625 | N2: =IF(ANÁLISIS_EQUIPO[[#This Row],[PESO]]=0,"SIN IMPACTO",IF(G2<=MAX(G$2:G$30)/4,"BAJO", IF(G2<=MAX(G$2:G$30)/2,"MEDIO", IF(G2<=MAX(G$2:G$30)*3/4,"ALTO","CRITICO")))) -> CRITICO | O2: =IF(COUNTIF(N$2:N2,N2)=1,SUMIF(N$2:N$30,N2,G$2:G$30),"") -> 0.375
A3: EMPRESARIAL ACTIVA | B3: 45917 | C3: ATENCIÓN TELEFÓNICA | D3: DIAGNÓSTICO | E3: Vender, | F3: 31.05 | G3: 0.125 | H3: 23.2875 | I3: 7.7625 | N3: =IF(ANÁLISIS_EQUIPO[[#This Row],[PESO]]=0,"SIN IMPACTO",IF(G3<=MAX(G$2:G$30)/4,"BAJO", IF(G3<=MAX(G$2:G$30)/2,"MEDIO", IF(G3<=MAX(G$2:G$30)*3/4,"ALTO","CRITICO")))) -> CRITICO | O3: =IF(COUNTIF(N$2:N3,N3)=1,SUMIF(N$2:N$30,N3,G$2:G$30),"")
A4: EMPRESARIAL ACTIVA | B4: 45917 | C4: ATENCIÓN TELEFÓNICA | D4: DIAGNÓSTICO | E4: Rebatir, | F4: 27.6 | G4: 0.11111111 | H4: 20.7 | I4: 6.9 | N4: =IF(ANÁLISIS_EQUIPO[[#This Row],[PESO]]=0,"SIN IMPACTO",IF(G4<=MAX(G$2:G$30)/4,"BAJO", IF(G4<=MAX(G$2:G$30)/2,"MEDIO", IF(G4<=MAX(G$2:G$30)*3/4,"ALTO","CRITICO")))) -> CRITICO | O4: =IF(COUNTIF(N$2:N4,N4)=1,SUMIF(N$2:N$30,N4,G$2:G$30),"")
A5: EMPRESARIAL ACTIVA | B5: 45917 | C5: ATENCIÓN TELEFÓNICA | D5: DIAGNÓSTICO | E5: Explica el motivo de la llamada de forma clara y rÃ¡pida, | F5: 24.15 | G5: 0.097222222 | H5: 18.1125 | I5: 6.0375 | N5: =IF(ANÁLISIS_EQUIPO[[#This Row],[PESO]]=0,"SIN IMPACTO",IF(G5<=MAX(G$2:G$30)/4,"BAJO", IF(G5<=MAX(G$2:G$30)/2,"MEDIO", IF(G5<=MAX(G$2:G$30)*3/4,"ALTO","CRITICO")))) -> ALTO | O5: =IF(COUNTIF(N$2:N5,N5)=1,SUMIF(N$2:N$30,N5,G$2:G$30),"") -> 0.097222222
A6: EMPRESARIAL ACTIVA | B6: 45917 | C6: ATENCIÓN TELEFÓNICA | D6: DIAGNÓSTICO | E6: Cierre, | F6: 17.25 | G6: 0.069444444 | H6: 12.9375 | I6: 4.3125 | N6: =IF(ANÁLISIS_EQUIPO[[#This Row],[PESO]]=0,"SIN IMPACTO",IF(G6<=MAX(G$2:G$30)/4,"BAJO", IF(G6<=MAX(G$2:G$30)/2,"MEDIO", IF(G6<=MAX(G$2:G$30)*3/4,"ALTO","CRITICO")))) -> MEDIO | O6: =IF(COUNTIF(N$2:N6,N6)=1,SUMIF(N$2:N$30,N6,G$2:G$30),"") -> 0.41666667 | Q6: CRITICO | R6: Q1 | S6: 10,6-14
A7: EMPRESARIAL ACTIVA | B7: 45917 | C7: ATENCIÓN TELEFÓNICA | D7: DIAGNÓSTICO | E7: Escucha Activa, | F7: 13.8 | G7: 0.055555556 | H7: 10.35 | I7: 3.45 | N7: =IF(ANÁLISIS_EQUIPO[[#This Row],[PESO]]=0,"SIN IMPACTO",IF(G7<=MAX(G$2:G$30)/4,"BAJO", IF(G7<=MAX(G$2:G$30)/2,"MEDIO", IF(G7<=MAX(G$2:G$30)*3/4,"ALTO","CRITICO")))) -> MEDIO | O7: =IF(COUNTIF(N$2:N7,N7)=1,SUMIF(N$2:N$30,N7,G$2:G$30),"") | Q7: ALTO | R7: Q2 | S7: 7,1-10,5
A8: EMPRESARIAL ACTIVA | B8: 45917 | C8: ATENCIÓN TELEFÓNICA | D8: DIAGNÓSTICO | E8: Preguntar, | F8: 13.8 | G8: 0.055555556 | H8: 10.35 | I8: 3.45 | N8: =IF(ANÁLISIS_EQUIPO[[#This Row],[PESO]]=0,"SIN IMPACTO",IF(G8<=MAX(G$2:G$30)/4,"BAJO", IF(G8<=MAX(G$2:G$30)/2,"MEDIO", IF(G8<=MAX(G$2:G$30)*3/4,"ALTO","CRITICO")))) -> MEDIO | O8: =IF(COUNTIF(N$2:N8,N8)=1,SUMIF(N$2:N$30,N8,G$2:G$30),"") | Q8: MEDIO | R8: Q3 | S8: 3,6-7
A9: EMPRESARIAL ACTIVA | B9: 45917 | C9: ATENCIÓN TELEFÓNICA | D9: DIAGNÓSTICO | E9: Despedida, | F9: 13.8 | G9: 0.055555556 | H9: 10.35 | I9: 3.45 | N9: =IF(ANÁLISIS_EQUIPO[[#This Row],[PESO]]=0,"SIN IMPACTO",IF(G9<=MAX(G$2:G$30)/4,"BAJO", IF(G9<=MAX(G$2:G$30)/2,"MEDIO", IF(G9<=MAX(G$2:G$30)*3/4,"ALTO","CRITICO")))) -> MEDIO | O9: =IF(COUNTIF(N$2:N9,N9)=1,SUMIF(N$2:N$30,N9,G$2:G$30),"") | Q9: BAJO | R9: Q4 | S9: 1-3,5
A10: EMPRESARIAL ACTIVA | B10: 45917 | C10: GESTIÓN EN CRM | D10: DIAGNÓSTICO | E10: TipificaciÃ³n, | F10: 13.8 | G10: 0.055555556 | H10: 10.35 | I10: 3.45 | N10: =IF(ANÁLISIS_EQUIPO[[#This Row],[PESO]]=0,"SIN IMPACTO",IF(G10<=MAX(G$2:G$30)/4,"BAJO", IF(G10<=MAX(G$2:G$30)/2,"MEDIO", IF(G10<=MAX(G$2:G$30)*3/4,"ALTO","CRITICO")))) -> MEDIO | O10: =IF(COUNTIF(N$2:N10,N10)=1,SUMIF(N$2:N$30,N10,G$2:G$30),"")
A11: EMPRESARIAL ACTIVA | B11: 45917 | C11: ATENCIÓN TELEFÓNICA | D11: DIAGNÓSTICO | E11: PresentaciÃ³n, | F11: 10.35 | G11: 0.041666667 | H11: 7.7625 | I11: 2.5875 | N11: =IF(ANÁLISIS_EQUIPO[[#This Row],[PESO]]=0,"SIN IMPACTO",IF(G11<=MAX(G$2:G$30)/4,"BAJO", IF(G11<=MAX(G$2:G$30)/2,"MEDIO", IF(G11<=MAX(G$2:G$30)*3/4,"ALTO","CRITICO")))) -> MEDIO | O11: =IF(COUNTIF(N$2:N11,N11)=1,SUMIF(N$2:N$30,N11,G$2:G$30),"")
A12: EMPRESARIAL ACTIVA | B12: 45917 | C12: IMPECABILIDAD | D12: DIAGNÓSTICO | E12: TMO | F12: 10.35 | G12: 0.041666667 | H12: 7.7625 | I12: 2.5875 | N12: =IF(ANÁLISIS_EQUIPO[[#This Row],[PESO]]=0,"SIN IMPACTO",IF(G12<=MAX(G$2:G$30)/4,"BAJO", IF(G12<=MAX(G$2:G$30)/2,"MEDIO", IF(G12<=MAX(G$2:G$30)*3/4,"ALTO","CRITICO")))) -> MEDIO | O12: =IF(COUNTIF(N$2:N12,N12)=1,SUMIF(N$2:N$30,N12,G$2:G$30),"")
A13: EMPRESARIAL ACTIVA | B13: 45917 | C13: IMPECABILIDAD | D13: DIAGNÓSTICO | E13: Manejo De Emociones, | F13: 10.35 | G13: 0.041666667 | H13: 7.7625 | I13: 2.5875 | N13: =IF(ANÁLISIS_EQUIPO[[#This Row],[PESO]]=0,"SIN IMPACTO",IF(G13<=MAX(G$2:G$30)/4,"BAJO", IF(G13<=MAX(G$2:G$30)/2,"MEDIO", IF(G13<=MAX(G$2:G$30)*3/4,"ALTO","CRITICO")))) -> MEDIO | O13: =IF(COUNTIF(N$2:N13,N13)=1,SUMIF(N$2:N$30,N13,G$2:G$30),"")
A14: EMPRESARIAL ACTIVA | B14: 45917 | C14: ATENCIÓN TELEFÓNICA | D14: DIAGNÓSTICO | E14: ActualizaciÃ³n de datos, | F14: 6.9 | G14: 0.027777778 | H14: 5.175 | I14: 1.725 | N14: =IF(ANÁLISIS_EQUIPO[[#This Row],[PESO]]=0,"SIN IMPACTO",IF(G14<=MAX(G$2:G$30)/4,"BAJO", IF(G14<=MAX(G$2:G$30)/2,"MEDIO", IF(G14<=MAX(G$2:G$30)*3/4,"ALTO","CRITICO")))) -> BAJO | O14: =IF(COUNTIF(N$2:N14,N14)=1,SUMIF(N$2:N$30,N14,G$2:G$30),"") -> 0.11111111
A15: EMPRESARIAL ACTIVA | B15: 45917 | C15: IMPECABILIDAD | D15: DIAGNÓSTICO | E15: Oferta, | F15: 6.9 | G15: 0.027777778 | H15: 5.175 | I15: 1.725 | N15: =IF(ANÁLISIS_EQUIPO[[#This Row],[PESO]]=0,"SIN IMPACTO",IF(G15<=MAX(G$2:G$30)/4,"BAJO", IF(G15<=MAX(G$2:G$30)/2,"MEDIO", IF(G15<=MAX(G$2:G$30)*3/4,"ALTO","CRITICO")))) -> BAJO | O15: =IF(COUNTIF(N$2:N15,N15)=1,SUMIF(N$2:N$30,N15,G$2:G$30),"")
A16: EMPRESARIAL ACTIVA | B16: 45917 | C16: IMPECABILIDAD | D16: DIAGNÓSTICO | E16: Conocimiento Del Producto | F16: 3.45 | G16: 0.013888889 | H16: 2.5875 | I16: 0.8625 | N16: =IF(ANÁLISIS_EQUIPO[[#This Row],[PESO]]=0,"SIN IMPACTO",IF(G16<=MAX(G$2:G$30)/4,"BAJO", IF(G16<=MAX(G$2:G$30)/2,"MEDIO", IF(G16<=MAX(G$2:G$30)*3/4,"ALTO","CRITICO")))) -> BAJO | O16: =IF(COUNTIF(N$2:N16,N16)=1,SUMIF(N$2:N$30,N16,G$2:G$30),"")
A17: EMPRESARIAL ACTIVA | B17: 45917 | C17: IMPECABILIDAD | D17: DIAGNÓSTICO | E17: Muletillas | F17: 3.45 | G17: 0.013888889 | H17: 2.5875 | I17: 0.8625 | N17: =IF(ANÁLISIS_EQUIPO[[#This Row],[PESO]]=0,"SIN IMPACTO",IF(G17<=MAX(G$2:G$30)/4,"BAJO", IF(G17<=MAX(G$2:G$30)/2,"MEDIO", IF(G17<=MAX(G$2:G$30)*3/4,"ALTO","CRITICO")))) -> BAJO | O17: =IF(COUNTIF(N$2:N17,N17)=1,SUMIF(N$2:N$30,N17,G$2:G$30),"")
A18: EMPRESARIAL ACTIVA | B18: 45917 | C18: GESTIÓN EN CRM | D18: DIAGNÓSTICO | E18: ObservaciÃ³n, | F18: 3.45 | G18: 0.013888889 | H18: 2.5875 | I18: 0.8625 | N18: =IF(ANÁLISIS_EQUIPO[[#This Row],[PESO]]=0,"SIN IMPACTO",IF(G18<=MAX(G$2:G$30)/4,"BAJO", IF(G18<=MAX(G$2:G$30)/2,"MEDIO", IF(G18<=MAX(G$2:G$30)*3/4,"ALTO","CRITICO")))) -> BAJO | O18: =IF(COUNTIF(N$2:N18,N18)=1,SUMIF(N$2:N$30,N18,G$2:G$30),"")
A19: EMPRESARIAL ACTIVA | B19: 45917 | C19: METODOLOGÍA DE GESTIÓN | D19: DIAGNÓSTICO | E19: Protocolo De GestiÃ³n | F19: 3.45 | G19: 0.013888889 | H19: 2.5875 | I19: 0.8625 | N19: =IF(ANÁLISIS_EQUIPO[[#This Row],[PESO]]=0,"SIN IMPACTO",IF(G19<=MAX(G$2:G$30)/4,"BAJO", IF(G19<=MAX(G$2:G$30)/2,"MEDIO", IF(G19<=MAX(G$2:G$30)*3/4,"ALTO","CRITICO")))) -> BAJO | O19: =IF(COUNTIF(N$2:N19,N19)=1,SUMIF(N$2:N$30,N19,G$2:G$30),"")
A20: EMPRESARIAL ACTIVA | B20: 45917 | C20: IMPECABILIDAD | D20: DIAGNÓSTICO | E20: ModulaciÃ³n | F20: 0 | G20: 0 | H20: 0 | I20: 0 | N20: =IF(ANÁLISIS_EQUIPO[[#This Row],[PESO]]=0,"SIN IMPACTO",IF(G20<=MAX(G$2:G$30)/4,"BAJO", IF(G20<=MAX(G$2:G$30)/2,"MEDIO", IF(G20<=MAX(G$2:G$30)*3/4,"ALTO","CRITICO")))) -> SIN IMPACTO | O20: =IF(COUNTIF(N$2:N20,N20)=1,SUMIF(N$2:N$30,N20,G$2:G$30),"") -> 0
A21: EMPRESARIAL ACTIVA | B21: 45917 | C21: IMPECABILIDAD | D21: DIAGNÓSTICO | E21: Ruido Ambiente | F21: 0 | G21: 0 | H21: 0 | I21: 0 | N21: =IF(ANÁLISIS_EQUIPO[[#This Row],[PESO]]=0,"SIN IMPACTO",IF(G21<=MAX(G$2:G$30)/4,"BAJO", IF(G21<=MAX(G$2:G$30)/2,"MEDIO", IF(G21<=MAX(G$2:G$30)*3/4,"ALTO","CRITICO")))) -> SIN IMPACTO | O21: =IF(COUNTIF(N$2:N21,N21)=1,SUMIF(N$2:N$30,N21,G$2:G$30),"")
... A30: EMPRESARIAL ACTIVA | B30: 45917 | C30: METODOLOGÍA DE GESTIÓN | D30: DIAGNÓSTICO | E30: Protocolo De GestiÃ³n, | F30: 0 | G30: 0 | H30: 0 | I30: 0 | N30: =IF(ANÁLISIS_EQUIPO[[#This Row],[PESO]]=0,"SIN IMPACTO",IF(G30<=MAX(G$2:G$30)/4,"BAJO", IF(G30<=MAX(G$2:G$30)/2,"MEDIO", IF(G30<=MAX(G$2:G$30)*3/4,"ALTO","CRITICO")))) -> SIN IMPACTO | O30: =IF(COUNTIF(N$2:N30,N30)=1,SUMIF(N$2:N$30,N30,G$2:G$30),"")
A31: EMPRESARIAL ACTIVA | B31: 45917 | C31: TOTAL | D31: TOTAL DIAGNÓSTICO | E31: TOTAL | F31: 248.4 | G31: 1 | H31: 186.3 | I31: 62.1 | J31: EMPEORA
A32: EMPRESARIAL ACTIVA | C32: ATENCIÓN TELEFÓNICA | D32: MONITOREO 1 | E32: PresentaciÃ³n, | F32: 17.25 | G32: 1 | H32: 1.940625 | I32: 8.409375 | J32: EMPEORA | N32: =IF(ANÁLISIS_EQUIPO[[#This Row],[PESO]]=0,"SIN IMPACTO",IF(G32<=MAX(G$32:G$60)/4,"BAJO", IF(G32<=MAX(G$32:G$60)/2,"MEDIO", IF(G32<=MAX(G$32:G$60)*3/4,"ALTO","CRITICO")))) -> CRITICO
A33: EMPRESARIAL ACTIVA | C33: ATENCIÓN TELEFÓNICA | D33: MONITOREO 1 | E33: Explica el motivo de la llamada de forma clara y rÃ¡pida, | F33: 0 | G33: 0 | H33: 4.528125 | I33: 19.621875 | J33: MEJORA | N33: =IF(ANÁLISIS_EQUIPO[[#This Row],[PESO]]=0,"SIN IMPACTO",IF(G33<=MAX(G$32:G$60)/4,"BAJO", IF(G33<=MAX(G$32:G$60)/2,"MEDIO", IF(G33<=MAX(G$32:G$60)*3/4,"ALTO","CRITICO")))) -> SIN IMPACTO
A34: EMPRESARIAL ACTIVA | C34: ATENCIÓN TELEFÓNICA | D34: MONITOREO 1 | E34: Escucha Activa, | F34: 0 | G34: 0 | H34: 2.5875 | I34: 11.2125 | J34: MEJORA | N34: =IF(ANÁLISIS_EQUIPO[[#This Row],[PESO]]=0,"SIN IMPACTO",IF(G34<=MAX(G$32:G$60)/4,"BAJO", IF(G34<=MAX(G$32:G$60)/2,"MEDIO", IF(G34<=MAX(G$32:G$60)*3/4,"ALTO","CRITICO")))) -> SIN IMPACTO
A35: EMPRESARIAL ACTIVA | C35: ATENCIÓN TELEFÓNICA | D35: MONITOREO 1 | E35: Preguntar, | F35: 0 | G35: 0 | H35: 2.5875 | I35: 11.2125 | J35: MEJORA | N35: =IF(ANÁLISIS_EQUIPO[[#This Row],[PESO]]=0,"SIN IMPACTO",IF(G35<=MAX(G$32:G$60)/4,"BAJO", IF(G35<=MAX(G$32:G$60)/2,"MEDIO", IF(G35<=MAX(G$32:G$60)*3/4,"ALTO","CRITICO")))) -> SIN IMPACTO
A36: EMPRESARIAL ACTIVA | C36: ATENCIÓN TELEFÓNICA | D36: MONITOREO 1 | E36: Rebatir, | F36: 0 | G36: 0 | H36: 5.175 | I36: 22.425 | J36: MEJORA | N36: =IF(ANÁLISIS_EQUIPO[[#This Row],[PESO]]=0,"SIN IMPACTO",IF(G36<=MAX(G$32:G$60)/4,"BAJO", IF(G36<=MAX(G$32:G$60)/2,"MEDIO", IF(G36<=MAX(G$32:G$60)*3/4,"ALTO","CRITICO")))) -> SIN IMPACTO
A37: EMPRESARIAL ACTIVA | C37: ATENCIÓN TELEFÓNICA | D37: MONITOREO 1 | E37: Vender, | F37: 0 | G37: 0 | H37: 5.821875 | I37: 25.228125 | J37: MEJORA | N37: =IF(ANÁLISIS_EQUIPO[[#This Row],[PESO]]=0,"SIN IMPACTO",IF(G37<=MAX(G$32:G$60)/4,"BAJO", IF(G37<=MAX(G$32:G$60)/2,"MEDIO", IF(G37<=MAX(G$32:G$60)*3/4,"ALTO","CRITICO")))) -> SIN IMPACTO
A38: EMPRESARIAL ACTIVA | C38: ATENCIÓN TELEFÓNICA | D38: MONITOREO 1 | E38: Beneficios, | F38: 0 | G38: 0 | H38: 6.46875 | I38: 28.03125 | J38: MEJORA | N38: =IF(ANÁLISIS_EQUIPO[[#This Row],[PESO]]=0,"SIN IMPACTO",IF(G38<=MAX(G$32:G$60)/4,"BAJO", IF(G38<=MAX(G$32:G$60)/2,"MEDIO", IF(G38<=MAX(G$32:G$60)*3/4,"ALTO","CRITICO")))) -> SIN IMPACTO
A39: EMPRESARIAL ACTIVA | C39: ATENCIÓN TELEFÓNICA | D39: MONITOREO 1 | E39: Cierre, | F39: 0 | G39: 0 | H39: 3.234375 | I39: 14.015625 | J39: MEJORA | N39: =IF(ANÁLISIS_EQUIPO[[#This Row],[PESO]]=0,"SIN IMPACTO",IF(G39<=MAX(G$32:G$60)/4,"BAJO", IF(G39<=MAX(G$32:G$60)/2,"MEDIO", IF(G39<=MAX(G$32:G$60)*3/4,"ALTO","CRITICO")))) -> SIN IMPACTO
A40: EMPRESARIAL ACTIVA | C40: ATENCIÓN TELEFÓNICA | D40: MONITOREO 1 | E40: ActualizaciÃ³n de datos, | F40: 0 | G40: 0 | H40: 1.29375 | I40: 5.60625 | J40: MEJORA | N40: =IF(ANÁLISIS_EQUIPO[[#This Row],[PESO]]=0,"SIN IMPACTO",IF(G40<=MAX(G$32:G$60)/4,"BAJO", IF(G40<=MAX(G$32:G$60)/2,"MEDIO", IF(G40<=MAX(G$32:G$60)*3/4,"ALTO","CRITICO")))) -> SIN IMPACTO
A41: EMPRESARIAL ACTIVA | C41: ATENCIÓN TELEFÓNICA | D41: MONITOREO 1 | E41: Despedida, | F41: 0 | G41: 0 | H41: 2.5875 | I41: 11.2125 | J41: MEJORA | N41: =IF(ANÁLISIS_EQUIPO[[#This Row],[PESO]]=0,"SIN IMPACTO",IF(G41<=MAX(G$32:G$60)/4,"BAJO", IF(G41<=MAX(G$32:G$60)/2,"MEDIO", IF(G41<=MAX(G$32:G$60)*3/4,"ALTO","CRITICO")))) -> SIN IMPACTO
A42: EMPRESARIAL ACTIVA | C42: IMPECABILIDAD | D42: MONITOREO 1 | E42: Oferta, | F42: 0 | G42: 0 | H42: 1.29375 | I42: 5.60625 | J42: MEJORA | N42: =IF(ANÁLISIS_EQUIPO[[#This Row],[PESO]]=0,"SIN IMPACTO",IF(G42<=MAX(G$32:G$60)/4,"BAJO", IF(G42<=MAX(G$32:G$60)/2,"MEDIO", IF(G42<=MAX(G$32:G$60)*3/4,"ALTO","CRITICO")))) -> SIN IMPACTO
A43: EMPRESARIAL ACTIVA | C43: IMPECABILIDAD | D43: MONITOREO 1 | E43: Conocimiento Del Producto | F43: 0 | G43: 0 | H43: 0.646875 | I43: 2.803125 | J43: MEJORA | N43: =IF(ANÁLISIS_EQUIPO[[#This Row],[PESO]]=0,"SIN IMPACTO",IF(G43<=MAX(G$32:G$60)/4,"BAJO", IF(G43<=MAX(G$32:G$60)/2,"MEDIO", IF(G43<=MAX(G$32:G$60)*3/4,"ALTO","CRITICO")))) -> SIN IMPACTO
... A60: EMPRESARIAL ACTIVA | C60: METODOLOGÍA DE GESTIÓN | D60: MONITOREO 1 | E60: Protocolo De GestiÃ³n | F60: 0 | G60: 0 | H60: 0.646875 | I60: 2.803125 | J60: MEJORA | N60: =IF(ANÁLISIS_EQUIPO[[#This Row],[PESO]]=0,"SIN IMPACTO",IF(G60<=MAX(G$32:G$60)/4,"BAJO", IF(G60<=MAX(G$32:G$60)/2,"MEDIO", IF(G60<=MAX(G$32:G$60)*3/4,"ALTO","CRITICO")))) -> SIN IMPACTO
A61: EMPRESARIAL ACTIVA | C61: TOTAL | D61: TOTAL MONITOREO 1 | E61: TOTAL | F61: 17.25 | G61: 1 | H61: 46.575 | I61: 201.825 | J61: MEJORA
A62: EMPRESARIAL ACTIVA | C62: ATENCIÓN TELEFÓNICA | D62: MONITOREO 2 | E62: PresentaciÃ³n, | F62: 0 | G62: 0 | H62: 1.940625 | I62: 6.46875 | J62: MEJORA | N62: =IF(ANÁLISIS_EQUIPO[[#This Row],[PESO]]=0,"SIN IMPACTO",IF(G62<=MAX(G$62:G$90)/4,"BAJO", IF(G62<=MAX(G$62:G$90)/2,"MEDIO", IF(G62<=MAX(G$62:G$90)*3/4,"ALTO","CRITICO")))) -> SIN IMPACTO
A63: EMPRESARIAL ACTIVA | C63: ATENCIÓN TELEFÓNICA | D63: MONITOREO 2 | E63: Explica el motivo de la llamada de forma clara y rÃ¡pida, | F63: 0 | G63: 0 | H63: 4.528125 | I63: 15.09375 | J63: MEJORA | N63: =IF(ANÁLISIS_EQUIPO[[#This Row],[PESO]]=0,"SIN IMPACTO",IF(G63<=MAX(G$62:G$90)/4,"BAJO", IF(G63<=MAX(G$62:G$90)/2,"MEDIO", IF(G63<=MAX(G$62:G$90)*3/4,"ALTO","CRITICO")))) -> SIN IMPACTO
A64: EMPRESARIAL ACTIVA | C64: ATENCIÓN TELEFÓNICA | D64: MONITOREO 2 | E64: Escucha Activa, | F64: 0 | G64: 0 | H64: 2.5875 | I64: 8.625 | J64: MEJORA | N64: =IF(ANÁLISIS_EQUIPO[[#This Row],[PESO]]=0,"SIN IMPACTO",IF(G64<=MAX(G$62:G$90)/4,"BAJO", IF(G64<=MAX(G$62:G$90)/2,"MEDIO", IF(G64<=MAX(G$62:G$90)*3/4,"ALTO","CRITICO")))) -> SIN IMPACTO
...

Sheet ANÁLISIS AGENTE
A1: PORTAFOLIO | B1: AGENTE | C1: FECHA | D1: SEGMENTO | E1: TIPO DE AUDITORÍA | F1: VARIABLE | G1: CALIFICACIÓN | H1: PESO | I1: IMPACTO TOTAL | J1: RESULTADO ESPERADO | K1: ESTADO | M1: SE MANTIENE | N1: MEJORA | O1: EMPEORA
A2: EMPRESARIAL ACTIVA | B2: CRISTIAN MAURICIO CIFUENTES CRUZ | C2: 45917 | D2: ATENCIÓN TELEFÓNICA | E2: DIAGNÓSTICO | F2: PresentaciÃ³n, | G2: {=TRANSPOSE(DIAGNÓSTICO!P7:AR7)} -> 0 | H2: =IFERROR((G2/$G$31),0) -> 0 | I2: =((G2)-(G2/4)) -> 0 | J2: =G2-I2 -> 0
A3: EMPRESARIAL ACTIVA | B3: CRISTIAN MAURICIO CIFUENTES CRUZ | C3: 45917 | D3: ATENCIÓN TELEFÓNICA | E3: DIAGNÓSTICO | F3: Explica el motivo de la llamada de forma clara y rÃ¡pida, | G3: 10.35 | H3: =IFERROR((G3/$G$31),0) -> 0.11111111 | I3: =((G3)-(G3/4)) -> 7.7625 | J3: =G3-I3 -> 2.5875
A4: EMPRESARIAL ACTIVA | B4: CRISTIAN MAURICIO CIFUENTES CRUZ | C4: 45917 | D4: ATENCIÓN TELEFÓNICA | E4: DIAGNÓSTICO | F4: Escucha Activa, | G4: 0 | H4: =IFERROR((G4/$G$31),0) -> 0 | I4: =((G4)-(G4/4)) -> 0 | J4: =G4-I4 -> 0
A5: EMPRESARIAL ACTIVA | B5: CRISTIAN MAURICIO CIFUENTES CRUZ | C5: 45917 | D5: ATENCIÓN TELEFÓNICA | E5: DIAGNÓSTICO | F5: Preguntar, | G5: 0 | H5: =IFERROR((G5/$G$31),0) -> 0 | I5: =((G5)-(G5/4)) -> 0 | J5: =G5-I5 -> 0
A6: EMPRESARIAL ACTIVA | B6: CRISTIAN MAURICIO CIFUENTES CRUZ | C6: 45917 | D6: ATENCIÓN TELEFÓNICA | E6: DIAGNÓSTICO | F6: Rebatir, | G6: 13.8 | H6: =IFERROR((G6/$G$31),0) -> 0.14814815 | I6: =((G6)-(G6/4)) -> 10.35 | J6: =G6-I6 -> 3.45
A7: EMPRESARIAL ACTIVA | B7: CRISTIAN MAURICIO CIFUENTES CRUZ | C7: 45917 | D7: ATENCIÓN TELEFÓNICA | E7: DIAGNÓSTICO | F7: Vender, | G7: 13.8 | H7: =IFERROR((G7/$G$31),0) -> 0.14814815 | I7: =((G7)-(G7/4)) -> 10.35 | J7: =G7-I7 -> 3.45
A8: EMPRESARIAL ACTIVA | B8: CRISTIAN MAURICIO CIFUENTES CRUZ | C8: 45917 | D8: ATENCIÓN TELEFÓNICA | E8: DIAGNÓSTICO | F8: Beneficios, | G8: 17.25 | H8: =IFERROR((G8/$G$31),0) -> 0.18518519 | I8: =((G8)-(G8/4)) -> 12.9375 | J8: =G8-I8 -> 4.3125
A9: EMPRESARIAL ACTIVA | B9: CRISTIAN MAURICIO CIFUENTES CRUZ | C9: 45917 | D9: ATENCIÓN TELEFÓNICA | E9: DIAGNÓSTICO | F9: Cierre, | G9: 13.8 | H9: =IFERROR((G9/$G$31),0) -> 0.14814815 | I9: =((G9)-(G9/4)) -> 10.35 | J9: =G9-I9 -> 3.45
A10: EMPRESARIAL ACTIVA | B10: CRISTIAN MAURICIO CIFUENTES CRUZ | C10: 45917 | D10: ATENCIÓN TELEFÓNICA | E10: DIAGNÓSTICO | F10: ActualizaciÃ³n de datos, | G10: 3.45 | H10: =IFERROR((G10/$G$31),0) -> 0.037037037 | I10: =((G10)-(G10/4)) -> 2.5875 | J10: =G10-I10 -> 0.8625
A11: EMPRESARIAL ACTIVA | B11: CRISTIAN MAURICIO CIFUENTES CRUZ | C11: 45917 | D11: ATENCIÓN TELEFÓNICA | E11: DIAGNÓSTICO | F11: Despedida, | G11: 10.35 | H11: =IFERROR((G11/$G$31),0) -> 0.11111111 | I11: =((G11)-(G11/4)) -> 7.7625 | J11: =G11-I11 -> 2.5875
A12: EMPRESARIAL ACTIVA | B12: CRISTIAN MAURICIO CIFUENTES CRUZ | C12: 45917 | D12: IMPECABILIDAD | E12: DIAGNÓSTICO | F12: Oferta, | G12: 3.45 | H12: =IFERROR((G12/$G$31),0) -> 0.037037037 | I12: =((G12)-(G12/4)) -> 2.5875 | J12: =G12-I12 -> 0.8625
A13: EMPRESARIAL ACTIVA | B13: CRISTIAN MAURICIO CIFUENTES CRUZ | C13: 45917 | D13: IMPECABILIDAD | E13: DIAGNÓSTICO | F13: Conocimiento Del Producto | G13: 0 | H13: =IFERROR((G13/$G$31),0) -> 0 | I13: =((G13)-(G13/4)) -> 0 | J13: =G13-I13 -> 0
A14: EMPRESARIAL ACTIVA | B14: CRISTIAN MAURICIO CIFUENTES CRUZ | C14: 45917 | D14: IMPECABILIDAD | E14: DIAGNÓSTICO | F14: ModulaciÃ³n | G14: 0 | H14: =IFERROR((G14/$G$31),0) -> 0 | I14: =((G14)-(G14/4)) -> 0 | J14: =G14-I14 -> 0
... A30: EMPRESARIAL ACTIVA | B30: CRISTIAN MAURICIO CIFUENTES CRUZ | C30: 45917 | D30: METODOLOGÍA DE GESTIÓN | E30: DIAGNÓSTICO | F30: Protocolo De GestiÃ³n | G30: 3.45 | H30: =IFERROR((G30/$G$31),0) -> 0.037037037 | I30: =((G30)-(G30/4)) -> 2.5875 | J30: =G30-I30 -> 0.8625
A31: EMPRESARIAL ACTIVA | B31: CRISTIAN MAURICIO CIFUENTES CRUZ | C31: 45917 | E31: DIAGNÓSTICO | G31: =SUM(G2:G30) -> 93.15 | H31: =SUM(H2:H30) -> 1 | I31: =SUM(I2:I30) -> 69.8625 | J31: =SUM(J2:J30) -> 23.2875
A32: EMPRESARIAL ACTIVA | B32: VALERIA GIRALDO RODRIGUEZ | C32: 45917 | D32: ATENCIÓN TELEFÓNICA | E32: DIAGNÓSTICO | F32: PresentaciÃ³n, | G32: {=TRANSPOSE(DIAGNÓSTICO!P13:AR13)} -> 6.9 | H32: =IFERROR((G32/$G$61),0) -> 0.10526316 | I32: =((G32)-(G32/4)) -> 5.175 | J32: =G32-I32 -> 1.725
A33: EMPRESARIAL ACTIVA | B33: VALERIA GIRALDO RODRIGUEZ | C33: 45917 | D33: ATENCIÓN TELEFÓNICA | E33: DIAGNÓSTICO | F33: Explica el motivo de la llamada de forma clara y rÃ¡pida, | G33: 10.35 | H33: =IFERROR((G33/$G$61),0) -> 0.15789474 | I33: =((G33)-(G33/4)) -> 7.7625 | J33: =G33-I33 -> 2.5875
A34: EMPRESARIAL ACTIVA | B34: VALERIA GIRALDO RODRIGUEZ | C34: 45917 | D34: ATENCIÓN TELEFÓNICA | E34: DIAGNÓSTICO | F34: Escucha Activa, | G34: 3.45 | H34: =IFERROR((G34/$G$61),0) -> 0.052631579 | I34: =((G34)-(G34/4)) -> 2.5875 | J34: =G34-I34 -> 0.8625
A35: EMPRESARIAL ACTIVA | B35: VALERIA GIRALDO RODRIGUEZ | C35: 45917 | D35: ATENCIÓN TELEFÓNICA | E35: DIAGNÓSTICO | F35: Preguntar, | G35: 6.9 | H35: =IFERROR((G35/$G$61),0) -> 0.10526316 | I35: =((G35)-(G35/4)) -> 5.175 | J35: =G35-I35 -> 1.725
A36: EMPRESARIAL ACTIVA | B36: VALERIA GIRALDO RODRIGUEZ | C36: 45917 | D36: ATENCIÓN TELEFÓNICA | E36: DIAGNÓSTICO | F36: Rebatir, | G36: 3.45 | H36: =IFERROR((G36/$G$61),0) -> 0.052631579 | I36: =((G36)-(G36/4)) -> 2.5875 | J36: =G36-I36 -> 0.8625
A37: EMPRESARIAL ACTIVA | B37: VALERIA GIRALDO RODRIGUEZ | C37: 45917 | D37: ATENCIÓN TELEFÓNICA | E37: DIAGNÓSTICO | F37: Vender, | G37: 6.9 | H37: =IFERROR((G37/$G$61),0) -> 0.10526316 | I37: =((G37)-(G37/4)) -> 5.175 | J37: =G37-I37 -> 1.725
